[2024-10-08T06:44:33.086+0000] {local_task_job_runner.py:123} INFO - ::group::Pre task execution logs
[2024-10-08T06:44:33.165+0000] {taskinstance.py:2612} INFO - Dependencies all met for dep_context=non-requeueable deps ti=<TaskInstance: compl_cssnowflake.science_assessment manual__2024-10-08T06:37:09.103495+00:00 [queued]>
[2024-10-08T06:44:33.188+0000] {taskinstance.py:2612} INFO - Dependencies all met for dep_context=requeueable deps ti=<TaskInstance: compl_cssnowflake.science_assessment manual__2024-10-08T06:37:09.103495+00:00 [queued]>
[2024-10-08T06:44:33.189+0000] {taskinstance.py:2865} INFO - Starting attempt 2 of 2
[2024-10-08T06:44:33.233+0000] {taskinstance.py:2888} INFO - Executing <Task(SnowflakeOperator): science_assessment> on 2024-10-08 06:37:09.103495+00:00
[2024-10-08T06:44:33.252+0000] {warnings.py:112} WARNING - /home/***/.local/lib/python3.12/site-packages/***/task/task_runner/standard_task_runner.py:70: DeprecationWarning: This process (pid=230) is multi-threaded, use of fork() may lead to deadlocks in the child.
  pid = os.fork()

[2024-10-08T06:44:33.252+0000] {standard_task_runner.py:104} INFO - Running: ['***', 'tasks', 'run', 'compl_cssnowflake', 'science_assessment', 'manual__2024-10-08T06:37:09.103495+00:00', '--job-id', '11', '--raw', '--subdir', 'DAGS_FOLDER/school/ty.py', '--cfg-path', '/tmp/tmpnidt0nap']
[2024-10-08T06:44:33.260+0000] {standard_task_runner.py:105} INFO - Job 11: Subtask science_assessment
[2024-10-08T06:44:33.259+0000] {standard_task_runner.py:72} INFO - Started process 232 to run task
[2024-10-08T06:44:33.363+0000] {task_command.py:467} INFO - Running <TaskInstance: compl_cssnowflake.science_assessment manual__2024-10-08T06:37:09.103495+00:00 [running]> on host 76e395cea755
[2024-10-08T06:44:33.500+0000] {taskinstance.py:3131} INFO - Exporting env vars: AIRFLOW_CTX_DAG_OWNER='seylow' AIRFLOW_CTX_DAG_ID='compl_cssnowflake' AIRFLOW_CTX_TASK_ID='science_assessment' AIRFLOW_CTX_EXECUTION_DATE='2024-10-08T06:37:09.103495+00:00' AIRFLOW_CTX_TRY_NUMBER='2' AIRFLOW_CTX_DAG_RUN_ID='manual__2024-10-08T06:37:09.103495+00:00'
[2024-10-08T06:44:33.502+0000] {logging_mixin.py:190} INFO - Task instance is in running state
[2024-10-08T06:44:33.505+0000] {logging_mixin.py:190} INFO -  Previous state of the Task instance: queued
[2024-10-08T06:44:33.507+0000] {logging_mixin.py:190} INFO - Current task name:science_assessment state:running start_date:2024-10-08 06:44:33.166496+00:00
[2024-10-08T06:44:33.508+0000] {logging_mixin.py:190} INFO - Dag name:compl_cssnowflake and current dag run status:running
[2024-10-08T06:44:33.509+0000] {taskinstance.py:731} INFO - ::endgroup::
[2024-10-08T06:44:33.510+0000] {sql.py:266} INFO - Executing: 
        CREATE OR REPLACE TEMPORARY TABLE temp_science_class AS
            SELECT * FROM school.data_schema.science_class WHERE 1 = 0;  -- Create an empty table with the same structure as the target

        COPY INTO temp_science_class
        FROM @school.data_schema.student
        PATTERN = 'science_class.csv'
        FILE_FORMAT = csv_format;

        MERGE INTO school.data_schema.science_class AS target
        USING temp_science_class AS source
        ON target.student_id = source.student_id  -- Match based on the unique identifier, like student_id
        WHEN NOT MATCHED THEN
        INSERT (student_id, Maths, English, Civic_education, Economics, Biology,
        Chemistry, Physics, Geography, Agric, Total_Grade_Points, Average_Score)
        VALUES (source.student_id, source.Maths, source.English, source.Civic_education,
        source.Economics, sources.Biology, source.Chemistry, source.Physics,
        source.Geography, source.Agric, source.Total_Grade_Points, source.Average_Score);
        drop TABLE temp_science_class;
    
[2024-10-08T06:44:33.532+0000] {base.py:84} INFO - Retrieving connection 'secondary'
[2024-10-08T06:44:33.553+0000] {base.py:84} INFO - Retrieving connection 'secondary'
[2024-10-08T06:44:33.558+0000] {connection.py:413} INFO - Snowflake Connector for Python Version: 3.12.1, Python Version: 3.12.5, Platform: Linux-5.15.153.1-microsoft-standard-WSL2-x86_64-with-glibc2.36
[2024-10-08T06:44:33.560+0000] {connection.py:1196} INFO - Connecting to GLOBAL Snowflake domain
[2024-10-08T06:44:33.561+0000] {connection.py:1277} INFO - This connection is in OCSP Fail Open Mode. TLS Certificates would be checked for validity and revocation status. Any other Certificate Revocation related exceptions or OCSP Responder failures would be disregarded in favor of connectivity.
[2024-10-08T06:44:36.472+0000] {taskinstance.py:3310} ERROR - Task failed with exception
Traceback (most recent call last):
  File "/home/airflow/.local/lib/python3.12/site-packages/airflow/models/taskinstance.py", line 767, in _execute_task
    result = _execute_callable(context=context, **execute_callable_kwargs)
             ^^^^^^^^^^^^^^^^^^^^^^^^^^^^^^^^^^^^^^^^^^^^^^^^^^^^^^^^^^^^^
  File "/home/airflow/.local/lib/python3.12/site-packages/airflow/models/taskinstance.py", line 733, in _execute_callable
    return ExecutionCallableRunner(
           ^^^^^^^^^^^^^^^^^^^^^^^^
  File "/home/airflow/.local/lib/python3.12/site-packages/airflow/utils/operator_helpers.py", line 252, in run
    return self.func(*args, **kwargs)
           ^^^^^^^^^^^^^^^^^^^^^^^^^^
  File "/home/airflow/.local/lib/python3.12/site-packages/airflow/models/baseoperator.py", line 406, in wrapper
    return func(self, *args, **kwargs)
           ^^^^^^^^^^^^^^^^^^^^^^^^^^^
  File "/home/airflow/.local/lib/python3.12/site-packages/airflow/providers/common/sql/operators/sql.py", line 272, in execute
    output = hook.run(
             ^^^^^^^^^
  File "/home/airflow/.local/lib/python3.12/site-packages/airflow/providers/snowflake/hooks/snowflake.py", line 404, in run
    with closing(self.get_conn()) as conn:
                 ^^^^^^^^^^^^^^^
  File "/home/airflow/.local/lib/python3.12/site-packages/airflow/providers/snowflake/hooks/snowflake.py", line 300, in get_conn
    conn = connector.connect(**conn_config)
           ^^^^^^^^^^^^^^^^^^^^^^^^^^^^^^^^
  File "/home/airflow/.local/lib/python3.12/site-packages/snowflake/connector/__init__.py", line 55, in Connect
    return SnowflakeConnection(**kwargs)
           ^^^^^^^^^^^^^^^^^^^^^^^^^^^^^
  File "/home/airflow/.local/lib/python3.12/site-packages/snowflake/connector/connection.py", line 456, in __init__
    self.connect(**kwargs)
  File "/home/airflow/.local/lib/python3.12/site-packages/snowflake/connector/connection.py", line 771, in connect
    self.__open_connection()
  File "/home/airflow/.local/lib/python3.12/site-packages/snowflake/connector/connection.py", line 1099, in __open_connection
    self.authenticate_with_retry(self.auth_class)
  File "/home/airflow/.local/lib/python3.12/site-packages/snowflake/connector/connection.py", line 1386, in authenticate_with_retry
    self._authenticate(auth_instance)
  File "/home/airflow/.local/lib/python3.12/site-packages/snowflake/connector/connection.py", line 1414, in _authenticate
    auth.authenticate(
  File "/home/airflow/.local/lib/python3.12/site-packages/snowflake/connector/auth/_auth.py", line 401, in authenticate
    Error.errorhandler_wrapper(
  File "/home/airflow/.local/lib/python3.12/site-packages/snowflake/connector/errors.py", line 284, in errorhandler_wrapper
    handed_over = Error.hand_to_other_handler(
                  ^^^^^^^^^^^^^^^^^^^^^^^^^^^^
  File "/home/airflow/.local/lib/python3.12/site-packages/snowflake/connector/errors.py", line 342, in hand_to_other_handler
    connection.errorhandler(connection, cursor, error_class, error_value)
  File "/home/airflow/.local/lib/python3.12/site-packages/snowflake/connector/errors.py", line 215, in default_errorhandler
    raise error_class(
snowflake.connector.errors.DatabaseError: 250001 (08001): None: Failed to connect to DB: de66153.eu-west-2.snowflakecomputing.com:443. Incorrect username or password was specified.
[2024-10-08T06:44:36.490+0000] {logging_mixin.py:190} INFO - Task instance in failure state
[2024-10-08T06:44:36.492+0000] {logging_mixin.py:190} INFO - Task start:2024-10-08 06:44:33.166496+00:00 end:2024-10-08 06:44:36.489892+00:00 duration:3.323396
[2024-10-08T06:44:36.493+0000] {logging_mixin.py:190} INFO - Task:<Task(SnowflakeOperator): science_assessment> dag:<DAG: compl_cssnowflake> dagrun:<DagRun compl_cssnowflake @ 2024-10-08 06:37:09.103495+00:00: manual__2024-10-08T06:37:09.103495+00:00, state:running, queued_at: 2024-10-08 06:44:10.798917+00:00. externally triggered: True>
[2024-10-08T06:44:36.494+0000] {logging_mixin.py:190} INFO - Failure caused by 250001 (08001): None: Failed to connect to DB: de66153.eu-west-2.snowflakecomputing.com:443. Incorrect username or password was specified.
[2024-10-08T06:44:36.495+0000] {taskinstance.py:1225} INFO - Marking task as FAILED. dag_id=compl_cssnowflake, task_id=science_assessment, run_id=manual__2024-10-08T06:37:09.103495+00:00, execution_date=20241008T063709, start_date=20241008T064433, end_date=20241008T064436
[2024-10-08T06:44:36.523+0000] {taskinstance.py:340} INFO - ::group::Post task execution logs
[2024-10-08T06:44:36.526+0000] {standard_task_runner.py:124} ERROR - Failed to execute job 11 for task science_assessment (250001 (08001): None: Failed to connect to DB: de66153.eu-west-2.snowflakecomputing.com:443. Incorrect username or password was specified.; 232)
Traceback (most recent call last):
  File "/home/airflow/.local/lib/python3.12/site-packages/airflow/task/task_runner/standard_task_runner.py", line 117, in _start_by_fork
    ret = args.func(args, dag=self.dag)
          ^^^^^^^^^^^^^^^^^^^^^^^^^^^^^
  File "/home/airflow/.local/lib/python3.12/site-packages/airflow/cli/cli_config.py", line 49, in command
    return func(*args, **kwargs)
           ^^^^^^^^^^^^^^^^^^^^^
  File "/home/airflow/.local/lib/python3.12/site-packages/airflow/utils/cli.py", line 115, in wrapper
    return f(*args, **kwargs)
           ^^^^^^^^^^^^^^^^^^
  File "/home/airflow/.local/lib/python3.12/site-packages/airflow/cli/commands/task_command.py", line 483, in task_run
    task_return_code = _run_task_by_selected_method(args, _dag, ti)
                       ^^^^^^^^^^^^^^^^^^^^^^^^^^^^^^^^^^^^^^^^^^^^
  File "/home/airflow/.local/lib/python3.12/site-packages/airflow/cli/commands/task_command.py", line 256, in _run_task_by_selected_method
    return _run_raw_task(args, ti)
           ^^^^^^^^^^^^^^^^^^^^^^^
  File "/home/airflow/.local/lib/python3.12/site-packages/airflow/cli/commands/task_command.py", line 341, in _run_raw_task
    return ti._run_raw_task(
           ^^^^^^^^^^^^^^^^^
  File "/home/airflow/.local/lib/python3.12/site-packages/airflow/utils/session.py", line 97, in wrapper
    return func(*args, session=session, **kwargs)
           ^^^^^^^^^^^^^^^^^^^^^^^^^^^^^^^^^^^^^^
  File "/home/airflow/.local/lib/python3.12/site-packages/airflow/models/taskinstance.py", line 3004, in _run_raw_task
    return _run_raw_task(
           ^^^^^^^^^^^^^^
  File "/home/airflow/.local/lib/python3.12/site-packages/airflow/models/taskinstance.py", line 273, in _run_raw_task
    TaskInstance._execute_task_with_callbacks(
  File "/home/airflow/.local/lib/python3.12/site-packages/airflow/models/taskinstance.py", line 3158, in _execute_task_with_callbacks
    result = self._execute_task(context, task_orig)
             ^^^^^^^^^^^^^^^^^^^^^^^^^^^^^^^^^^^^^^
  File "/home/airflow/.local/lib/python3.12/site-packages/airflow/models/taskinstance.py", line 3182, in _execute_task
    return _execute_task(self, context, task_orig)
           ^^^^^^^^^^^^^^^^^^^^^^^^^^^^^^^^^^^^^^^
  File "/home/airflow/.local/lib/python3.12/site-packages/airflow/models/taskinstance.py", line 767, in _execute_task
    result = _execute_callable(context=context, **execute_callable_kwargs)
             ^^^^^^^^^^^^^^^^^^^^^^^^^^^^^^^^^^^^^^^^^^^^^^^^^^^^^^^^^^^^^
  File "/home/airflow/.local/lib/python3.12/site-packages/airflow/models/taskinstance.py", line 733, in _execute_callable
    return ExecutionCallableRunner(
           ^^^^^^^^^^^^^^^^^^^^^^^^
  File "/home/airflow/.local/lib/python3.12/site-packages/airflow/utils/operator_helpers.py", line 252, in run
    return self.func(*args, **kwargs)
           ^^^^^^^^^^^^^^^^^^^^^^^^^^
  File "/home/airflow/.local/lib/python3.12/site-packages/airflow/models/baseoperator.py", line 406, in wrapper
    return func(self, *args, **kwargs)
           ^^^^^^^^^^^^^^^^^^^^^^^^^^^
  File "/home/airflow/.local/lib/python3.12/site-packages/airflow/providers/common/sql/operators/sql.py", line 272, in execute
    output = hook.run(
             ^^^^^^^^^
  File "/home/airflow/.local/lib/python3.12/site-packages/airflow/providers/snowflake/hooks/snowflake.py", line 404, in run
    with closing(self.get_conn()) as conn:
                 ^^^^^^^^^^^^^^^
  File "/home/airflow/.local/lib/python3.12/site-packages/airflow/providers/snowflake/hooks/snowflake.py", line 300, in get_conn
    conn = connector.connect(**conn_config)
           ^^^^^^^^^^^^^^^^^^^^^^^^^^^^^^^^
  File "/home/airflow/.local/lib/python3.12/site-packages/snowflake/connector/__init__.py", line 55, in Connect
    return SnowflakeConnection(**kwargs)
           ^^^^^^^^^^^^^^^^^^^^^^^^^^^^^
  File "/home/airflow/.local/lib/python3.12/site-packages/snowflake/connector/connection.py", line 456, in __init__
    self.connect(**kwargs)
  File "/home/airflow/.local/lib/python3.12/site-packages/snowflake/connector/connection.py", line 771, in connect
    self.__open_connection()
  File "/home/airflow/.local/lib/python3.12/site-packages/snowflake/connector/connection.py", line 1099, in __open_connection
    self.authenticate_with_retry(self.auth_class)
  File "/home/airflow/.local/lib/python3.12/site-packages/snowflake/connector/connection.py", line 1386, in authenticate_with_retry
    self._authenticate(auth_instance)
  File "/home/airflow/.local/lib/python3.12/site-packages/snowflake/connector/connection.py", line 1414, in _authenticate
    auth.authenticate(
  File "/home/airflow/.local/lib/python3.12/site-packages/snowflake/connector/auth/_auth.py", line 401, in authenticate
    Error.errorhandler_wrapper(
  File "/home/airflow/.local/lib/python3.12/site-packages/snowflake/connector/errors.py", line 284, in errorhandler_wrapper
    handed_over = Error.hand_to_other_handler(
                  ^^^^^^^^^^^^^^^^^^^^^^^^^^^^
  File "/home/airflow/.local/lib/python3.12/site-packages/snowflake/connector/errors.py", line 342, in hand_to_other_handler
    connection.errorhandler(connection, cursor, error_class, error_value)
  File "/home/airflow/.local/lib/python3.12/site-packages/snowflake/connector/errors.py", line 215, in default_errorhandler
    raise error_class(
snowflake.connector.errors.DatabaseError: 250001 (08001): None: Failed to connect to DB: de66153.eu-west-2.snowflakecomputing.com:443. Incorrect username or password was specified.
[2024-10-08T06:44:36.580+0000] {local_task_job_runner.py:266} INFO - Task exited with return code 1
[2024-10-08T06:44:36.624+0000] {taskinstance.py:3900} INFO - 0 downstream tasks scheduled from follow-on schedule check
[2024-10-08T06:44:36.630+0000] {local_task_job_runner.py:245} INFO - ::endgroup::
