[2024-10-17T22:29:58.650+0000] {local_task_job_runner.py:123} INFO - ::group::Pre task execution logs
[2024-10-17T22:29:58.686+0000] {taskinstance.py:2612} INFO - Dependencies all met for dep_context=non-requeueable deps ti=<TaskInstance: postgres_to_s3.bash_task1 manual__2024-10-17T22:13:22.823801+00:00 [queued]>
[2024-10-17T22:29:58.702+0000] {taskinstance.py:2612} INFO - Dependencies all met for dep_context=requeueable deps ti=<TaskInstance: postgres_to_s3.bash_task1 manual__2024-10-17T22:13:22.823801+00:00 [queued]>
[2024-10-17T22:29:58.703+0000] {taskinstance.py:2865} INFO - Starting attempt 7 of 7
[2024-10-17T22:29:58.736+0000] {taskinstance.py:2888} INFO - Executing <Task(BashOperator): bash_task1> on 2024-10-17 22:13:22.823801+00:00
[2024-10-17T22:29:58.746+0000] {warnings.py:112} WARNING - /home/***/.local/lib/python3.12/site-packages/***/task/task_runner/standard_task_runner.py:70: DeprecationWarning: This process (pid=2343) is multi-threaded, use of fork() may lead to deadlocks in the child.
  pid = os.fork()

[2024-10-17T22:29:58.749+0000] {standard_task_runner.py:72} INFO - Started process 2345 to run task
[2024-10-17T22:29:58.755+0000] {standard_task_runner.py:104} INFO - Running: ['***', 'tasks', 'run', 'postgres_to_s3', 'bash_task1', 'manual__2024-10-17T22:13:22.823801+00:00', '--job-id', '84', '--raw', '--subdir', 'DAGS_FOLDER/prod.py', '--cfg-path', '/tmp/tmpe4g4bwgu']
[2024-10-17T22:29:58.760+0000] {standard_task_runner.py:105} INFO - Job 84: Subtask bash_task1
[2024-10-17T22:29:58.856+0000] {task_command.py:467} INFO - Running <TaskInstance: postgres_to_s3.bash_task1 manual__2024-10-17T22:13:22.823801+00:00 [running]> on host 1b4cad12ae67
[2024-10-17T22:29:59.014+0000] {taskinstance.py:3131} INFO - Exporting env vars: AIRFLOW_CTX_DAG_OWNER='protectorate' AIRFLOW_CTX_DAG_ID='postgres_to_s3' AIRFLOW_CTX_TASK_ID='bash_task1' AIRFLOW_CTX_EXECUTION_DATE='2024-10-17T22:13:22.823801+00:00' AIRFLOW_CTX_TRY_NUMBER='7' AIRFLOW_CTX_DAG_RUN_ID='manual__2024-10-17T22:13:22.823801+00:00'
[2024-10-17T22:29:59.016+0000] {taskinstance.py:731} INFO - ::endgroup::
[2024-10-17T22:29:59.045+0000] {subprocess.py:63} INFO - Tmp dir root location: /tmp
[2024-10-17T22:29:59.046+0000] {subprocess.py:75} INFO - Running command: ['/usr/bin/bash', '-c', './opt/***/dags/wiki_log_file.sh ']
[2024-10-17T22:29:59.064+0000] {subprocess.py:86} INFO - Output:
[2024-10-17T22:29:59.067+0000] {subprocess.py:93} INFO - /usr/bin/bash: line 1: ./opt/***/dags/wiki_log_file.sh: No such file or directory
[2024-10-17T22:29:59.068+0000] {subprocess.py:97} INFO - Command exited with return code 127
[2024-10-17T22:29:59.084+0000] {taskinstance.py:3310} ERROR - Task failed with exception
Traceback (most recent call last):
  File "/home/airflow/.local/lib/python3.12/site-packages/airflow/models/taskinstance.py", line 767, in _execute_task
    result = _execute_callable(context=context, **execute_callable_kwargs)
             ^^^^^^^^^^^^^^^^^^^^^^^^^^^^^^^^^^^^^^^^^^^^^^^^^^^^^^^^^^^^^
  File "/home/airflow/.local/lib/python3.12/site-packages/airflow/models/taskinstance.py", line 733, in _execute_callable
    return ExecutionCallableRunner(
           ^^^^^^^^^^^^^^^^^^^^^^^^
  File "/home/airflow/.local/lib/python3.12/site-packages/airflow/utils/operator_helpers.py", line 252, in run
    return self.func(*args, **kwargs)
           ^^^^^^^^^^^^^^^^^^^^^^^^^^
  File "/home/airflow/.local/lib/python3.12/site-packages/airflow/models/baseoperator.py", line 406, in wrapper
    return func(self, *args, **kwargs)
           ^^^^^^^^^^^^^^^^^^^^^^^^^^^
  File "/home/airflow/.local/lib/python3.12/site-packages/airflow/operators/bash.py", line 249, in execute
    raise AirflowException(
airflow.exceptions.AirflowException: Bash command failed. The command returned a non-zero exit code 127.
[2024-10-17T22:29:59.092+0000] {taskinstance.py:1225} INFO - Marking task as FAILED. dag_id=postgres_to_s3, task_id=bash_task1, run_id=manual__2024-10-17T22:13:22.823801+00:00, execution_date=20241017T221322, start_date=20241017T222958, end_date=20241017T222959
[2024-10-17T22:29:59.114+0000] {taskinstance.py:340} INFO - ::group::Post task execution logs
[2024-10-17T22:29:59.115+0000] {standard_task_runner.py:124} ERROR - Failed to execute job 84 for task bash_task1 (Bash command failed. The command returned a non-zero exit code 127.; 2345)
Traceback (most recent call last):
  File "/home/airflow/.local/lib/python3.12/site-packages/airflow/task/task_runner/standard_task_runner.py", line 117, in _start_by_fork
    ret = args.func(args, dag=self.dag)
          ^^^^^^^^^^^^^^^^^^^^^^^^^^^^^
  File "/home/airflow/.local/lib/python3.12/site-packages/airflow/cli/cli_config.py", line 49, in command
    return func(*args, **kwargs)
           ^^^^^^^^^^^^^^^^^^^^^
  File "/home/airflow/.local/lib/python3.12/site-packages/airflow/utils/cli.py", line 115, in wrapper
    return f(*args, **kwargs)
           ^^^^^^^^^^^^^^^^^^
  File "/home/airflow/.local/lib/python3.12/site-packages/airflow/cli/commands/task_command.py", line 483, in task_run
    task_return_code = _run_task_by_selected_method(args, _dag, ti)
                       ^^^^^^^^^^^^^^^^^^^^^^^^^^^^^^^^^^^^^^^^^^^^
  File "/home/airflow/.local/lib/python3.12/site-packages/airflow/cli/commands/task_command.py", line 256, in _run_task_by_selected_method
    return _run_raw_task(args, ti)
           ^^^^^^^^^^^^^^^^^^^^^^^
  File "/home/airflow/.local/lib/python3.12/site-packages/airflow/cli/commands/task_command.py", line 341, in _run_raw_task
    return ti._run_raw_task(
           ^^^^^^^^^^^^^^^^^
  File "/home/airflow/.local/lib/python3.12/site-packages/airflow/utils/session.py", line 97, in wrapper
    return func(*args, session=session, **kwargs)
           ^^^^^^^^^^^^^^^^^^^^^^^^^^^^^^^^^^^^^^
  File "/home/airflow/.local/lib/python3.12/site-packages/airflow/models/taskinstance.py", line 3004, in _run_raw_task
    return _run_raw_task(
           ^^^^^^^^^^^^^^
  File "/home/airflow/.local/lib/python3.12/site-packages/airflow/models/taskinstance.py", line 273, in _run_raw_task
    TaskInstance._execute_task_with_callbacks(
  File "/home/airflow/.local/lib/python3.12/site-packages/airflow/models/taskinstance.py", line 3158, in _execute_task_with_callbacks
    result = self._execute_task(context, task_orig)
             ^^^^^^^^^^^^^^^^^^^^^^^^^^^^^^^^^^^^^^
  File "/home/airflow/.local/lib/python3.12/site-packages/airflow/models/taskinstance.py", line 3182, in _execute_task
    return _execute_task(self, context, task_orig)
           ^^^^^^^^^^^^^^^^^^^^^^^^^^^^^^^^^^^^^^^
  File "/home/airflow/.local/lib/python3.12/site-packages/airflow/models/taskinstance.py", line 767, in _execute_task
    result = _execute_callable(context=context, **execute_callable_kwargs)
             ^^^^^^^^^^^^^^^^^^^^^^^^^^^^^^^^^^^^^^^^^^^^^^^^^^^^^^^^^^^^^
  File "/home/airflow/.local/lib/python3.12/site-packages/airflow/models/taskinstance.py", line 733, in _execute_callable
    return ExecutionCallableRunner(
           ^^^^^^^^^^^^^^^^^^^^^^^^
  File "/home/airflow/.local/lib/python3.12/site-packages/airflow/utils/operator_helpers.py", line 252, in run
    return self.func(*args, **kwargs)
           ^^^^^^^^^^^^^^^^^^^^^^^^^^
  File "/home/airflow/.local/lib/python3.12/site-packages/airflow/models/baseoperator.py", line 406, in wrapper
    return func(self, *args, **kwargs)
           ^^^^^^^^^^^^^^^^^^^^^^^^^^^
  File "/home/airflow/.local/lib/python3.12/site-packages/airflow/operators/bash.py", line 249, in execute
    raise AirflowException(
airflow.exceptions.AirflowException: Bash command failed. The command returned a non-zero exit code 127.
[2024-10-17T22:29:59.135+0000] {local_task_job_runner.py:266} INFO - Task exited with return code 1
[2024-10-17T22:29:59.174+0000] {taskinstance.py:3900} INFO - 0 downstream tasks scheduled from follow-on schedule check
[2024-10-17T22:29:59.184+0000] {local_task_job_runner.py:245} INFO - ::endgroup::
