[2024-10-13T23:09:12.527+0000] {local_task_job_runner.py:123} INFO - ::group::Pre task execution logs
[2024-10-13T23:09:12.551+0000] {taskinstance.py:2612} INFO - Dependencies all met for dep_context=non-requeueable deps ti=<TaskInstance: adewunmi.execute_bash_command manual__2024-10-13T23:05:58.528395+00:00 [queued]>
[2024-10-13T23:09:12.564+0000] {taskinstance.py:2612} INFO - Dependencies all met for dep_context=requeueable deps ti=<TaskInstance: adewunmi.execute_bash_command manual__2024-10-13T23:05:58.528395+00:00 [queued]>
[2024-10-13T23:09:12.564+0000] {taskinstance.py:2865} INFO - Starting attempt 4 of 4
[2024-10-13T23:09:12.587+0000] {taskinstance.py:2888} INFO - Executing <Task(BashOperator): execute_bash_command> on 2024-10-13 23:05:58.528395+00:00
[2024-10-13T23:09:12.594+0000] {warnings.py:112} WARNING - /home/***/.local/lib/python3.12/site-packages/***/task/task_runner/standard_task_runner.py:70: DeprecationWarning: This process (pid=309) is multi-threaded, use of fork() may lead to deadlocks in the child.
  pid = os.fork()

[2024-10-13T23:09:12.596+0000] {standard_task_runner.py:72} INFO - Started process 310 to run task
[2024-10-13T23:09:12.596+0000] {standard_task_runner.py:104} INFO - Running: ['***', 'tasks', 'run', 'adewunmi', 'execute_bash_command', 'manual__2024-10-13T23:05:58.528395+00:00', '--job-id', '11', '--raw', '--subdir', 'DAGS_FOLDER/email.py', '--cfg-path', '/tmp/tmpfxvjrd9n']
[2024-10-13T23:09:12.597+0000] {standard_task_runner.py:105} INFO - Job 11: Subtask execute_bash_command
[2024-10-13T23:09:12.662+0000] {task_command.py:467} INFO - Running <TaskInstance: adewunmi.execute_bash_command manual__2024-10-13T23:05:58.528395+00:00 [running]> on host 1b4cad12ae67
[2024-10-13T23:09:12.789+0000] {taskinstance.py:3131} INFO - Exporting env vars: AIRFLOW_CTX_DAG_OWNER='adewunmi' AIRFLOW_CTX_DAG_ID='adewunmi' AIRFLOW_CTX_TASK_ID='execute_bash_command' AIRFLOW_CTX_EXECUTION_DATE='2024-10-13T23:05:58.528395+00:00' AIRFLOW_CTX_TRY_NUMBER='4' AIRFLOW_CTX_DAG_RUN_ID='manual__2024-10-13T23:05:58.528395+00:00'
[2024-10-13T23:09:12.790+0000] {taskinstance.py:731} INFO - ::endgroup::
[2024-10-13T23:09:12.840+0000] {subprocess.py:63} INFO - Tmp dir root location: /tmp
[2024-10-13T23:09:12.842+0000] {subprocess.py:75} INFO - Running command: ['/usr/bin/bash', '-c', 'echo "Hello, world!']
[2024-10-13T23:09:12.854+0000] {subprocess.py:86} INFO - Output:
[2024-10-13T23:09:12.856+0000] {subprocess.py:93} INFO - /usr/bin/bash: -c: line 1: unexpected EOF while looking for matching `"'
[2024-10-13T23:09:12.857+0000] {subprocess.py:97} INFO - Command exited with return code 2
[2024-10-13T23:09:12.872+0000] {taskinstance.py:3310} ERROR - Task failed with exception
Traceback (most recent call last):
  File "/home/airflow/.local/lib/python3.12/site-packages/airflow/models/taskinstance.py", line 767, in _execute_task
    result = _execute_callable(context=context, **execute_callable_kwargs)
             ^^^^^^^^^^^^^^^^^^^^^^^^^^^^^^^^^^^^^^^^^^^^^^^^^^^^^^^^^^^^^
  File "/home/airflow/.local/lib/python3.12/site-packages/airflow/models/taskinstance.py", line 733, in _execute_callable
    return ExecutionCallableRunner(
           ^^^^^^^^^^^^^^^^^^^^^^^^
  File "/home/airflow/.local/lib/python3.12/site-packages/airflow/utils/operator_helpers.py", line 252, in run
    return self.func(*args, **kwargs)
           ^^^^^^^^^^^^^^^^^^^^^^^^^^
  File "/home/airflow/.local/lib/python3.12/site-packages/airflow/models/baseoperator.py", line 406, in wrapper
    return func(self, *args, **kwargs)
           ^^^^^^^^^^^^^^^^^^^^^^^^^^^
  File "/home/airflow/.local/lib/python3.12/site-packages/airflow/operators/bash.py", line 249, in execute
    raise AirflowException(
airflow.exceptions.AirflowException: Bash command failed. The command returned a non-zero exit code 2.
[2024-10-13T23:09:12.882+0000] {taskinstance.py:1225} INFO - Marking task as FAILED. dag_id=adewunmi, task_id=execute_bash_command, run_id=manual__2024-10-13T23:05:58.528395+00:00, execution_date=20241013T230558, start_date=20241013T230912, end_date=20241013T230912
[2024-10-13T23:09:12.883+0000] {taskinstance.py:1563} INFO - Executing callback at index 0: task_fail_alert
[2024-10-13T23:09:12.885+0000] {logging_mixin.py:190} INFO - {'conf': <***.configuration.AirflowConfigParser object at 0x7fe8eb814cb0>, 'dag': <DAG: adewunmi>, 'dag_run': <DagRun adewunmi @ 2024-10-13 23:05:58.528395+00:00: manual__2024-10-13T23:05:58.528395+00:00, state:running, queued_at: 2024-10-13 23:09:04.712327+00:00. externally triggered: True>, 'data_interval_end': DateTime(2024, 10, 13, 23, 5, 58, 528395, tzinfo=Timezone('UTC')), 'data_interval_start': DateTime(2024, 10, 13, 23, 5, 58, 528395, tzinfo=Timezone('UTC')), 'outlet_events': <***.utils.context.OutletEventAccessors object at 0x7fe8eb8d4410>, 'ds': '2024-10-13', 'ds_nodash': '20241013', 'execution_date': DateTime(2024, 10, 13, 23, 5, 58, 528395, tzinfo=Timezone('UTC')), 'expanded_ti_count': None, 'inlets': [], 'inlet_events': InletEventsAccessors(_inlets=[], _datasets={}, _dataset_aliases={}, _session=<sqlalchemy.orm.session.Session object at 0x7fe8eb8d4f20>), 'logical_date': DateTime(2024, 10, 13, 23, 5, 58, 528395, tzinfo=Timezone('UTC')), 'macros': <module '***.macros' from '/home/***/.local/lib/python3.12/site-packages/***/macros/__init__.py'>, 'map_index_template': None, 'next_ds': '2024-10-13', 'next_ds_nodash': '20241013', 'next_execution_date': DateTime(2024, 10, 13, 23, 5, 58, 528395, tzinfo=Timezone('UTC')), 'outlets': [], 'params': {}, 'prev_data_interval_start_success': DateTime(2024, 10, 13, 22, 41, 57, 200069, tzinfo=Timezone('UTC')), 'prev_data_interval_end_success': DateTime(2024, 10, 13, 22, 41, 57, 200069, tzinfo=Timezone('UTC')), 'prev_ds': '2024-10-13', 'prev_ds_nodash': '20241013', 'prev_execution_date': DateTime(2024, 10, 13, 23, 5, 58, 528395, tzinfo=Timezone('UTC')), 'prev_execution_date_success': DateTime(2024, 10, 13, 22, 41, 57, 200069, tzinfo=Timezone('UTC')), 'prev_start_date_success': DateTime(2024, 10, 13, 22, 52, 35, 993597, tzinfo=Timezone('UTC')), 'prev_end_date_success': DateTime(2024, 10, 13, 22, 52, 41, 281560, tzinfo=Timezone('UTC')), 'run_id': 'manual__2024-10-13T23:05:58.528395+00:00', 'task': <Task(BashOperator): execute_bash_command>, 'task_instance': <TaskInstance: adewunmi.execute_bash_command manual__2024-10-13T23:05:58.528395+00:00 [failed]>, 'task_instance_key_str': 'adewunmi__execute_bash_command__20241013', 'test_mode': False, 'ti': <TaskInstance: adewunmi.execute_bash_command manual__2024-10-13T23:05:58.528395+00:00 [failed]>, 'tomorrow_ds': '2024-10-14', 'tomorrow_ds_nodash': '20241014', 'triggering_dataset_events': <Proxy at 0x7fe8d98b9480 with factory <function _get_template_context.<locals>.get_triggering_events at 0x7fe8d9a5b880>>, 'ts': '2024-10-13T23:05:58.528395+00:00', 'ts_nodash': '20241013T230558', 'ts_nodash_with_tz': '20241013T230558.528395+0000', 'var': {'json': None, 'value': None}, 'conn': None, 'yesterday_ds': '2024-10-12', 'yesterday_ds_nodash': '20241012', 'exception': AirflowException('Bash command failed. The command returned a non-zero exit code 2.')}
[2024-10-13T23:09:15.758+0000] {logging_mixin.py:190} INFO - Email Sent Successfully
[2024-10-13T23:09:16.017+0000] {taskinstance.py:340} INFO - ::group::Post task execution logs
[2024-10-13T23:09:16.019+0000] {standard_task_runner.py:124} ERROR - Failed to execute job 11 for task execute_bash_command (Bash command failed. The command returned a non-zero exit code 2.; 310)
Traceback (most recent call last):
  File "/home/airflow/.local/lib/python3.12/site-packages/airflow/task/task_runner/standard_task_runner.py", line 117, in _start_by_fork
    ret = args.func(args, dag=self.dag)
          ^^^^^^^^^^^^^^^^^^^^^^^^^^^^^
  File "/home/airflow/.local/lib/python3.12/site-packages/airflow/cli/cli_config.py", line 49, in command
    return func(*args, **kwargs)
           ^^^^^^^^^^^^^^^^^^^^^
  File "/home/airflow/.local/lib/python3.12/site-packages/airflow/utils/cli.py", line 115, in wrapper
    return f(*args, **kwargs)
           ^^^^^^^^^^^^^^^^^^
  File "/home/airflow/.local/lib/python3.12/site-packages/airflow/cli/commands/task_command.py", line 483, in task_run
    task_return_code = _run_task_by_selected_method(args, _dag, ti)
                       ^^^^^^^^^^^^^^^^^^^^^^^^^^^^^^^^^^^^^^^^^^^^
  File "/home/airflow/.local/lib/python3.12/site-packages/airflow/cli/commands/task_command.py", line 256, in _run_task_by_selected_method
    return _run_raw_task(args, ti)
           ^^^^^^^^^^^^^^^^^^^^^^^
  File "/home/airflow/.local/lib/python3.12/site-packages/airflow/cli/commands/task_command.py", line 341, in _run_raw_task
    return ti._run_raw_task(
           ^^^^^^^^^^^^^^^^^
  File "/home/airflow/.local/lib/python3.12/site-packages/airflow/utils/session.py", line 97, in wrapper
    return func(*args, session=session, **kwargs)
           ^^^^^^^^^^^^^^^^^^^^^^^^^^^^^^^^^^^^^^
  File "/home/airflow/.local/lib/python3.12/site-packages/airflow/models/taskinstance.py", line 3004, in _run_raw_task
    return _run_raw_task(
           ^^^^^^^^^^^^^^
  File "/home/airflow/.local/lib/python3.12/site-packages/airflow/models/taskinstance.py", line 273, in _run_raw_task
    TaskInstance._execute_task_with_callbacks(
  File "/home/airflow/.local/lib/python3.12/site-packages/airflow/models/taskinstance.py", line 3158, in _execute_task_with_callbacks
    result = self._execute_task(context, task_orig)
             ^^^^^^^^^^^^^^^^^^^^^^^^^^^^^^^^^^^^^^
  File "/home/airflow/.local/lib/python3.12/site-packages/airflow/models/taskinstance.py", line 3182, in _execute_task
    return _execute_task(self, context, task_orig)
           ^^^^^^^^^^^^^^^^^^^^^^^^^^^^^^^^^^^^^^^
  File "/home/airflow/.local/lib/python3.12/site-packages/airflow/models/taskinstance.py", line 767, in _execute_task
    result = _execute_callable(context=context, **execute_callable_kwargs)
             ^^^^^^^^^^^^^^^^^^^^^^^^^^^^^^^^^^^^^^^^^^^^^^^^^^^^^^^^^^^^^
  File "/home/airflow/.local/lib/python3.12/site-packages/airflow/models/taskinstance.py", line 733, in _execute_callable
    return ExecutionCallableRunner(
           ^^^^^^^^^^^^^^^^^^^^^^^^
  File "/home/airflow/.local/lib/python3.12/site-packages/airflow/utils/operator_helpers.py", line 252, in run
    return self.func(*args, **kwargs)
           ^^^^^^^^^^^^^^^^^^^^^^^^^^
  File "/home/airflow/.local/lib/python3.12/site-packages/airflow/models/baseoperator.py", line 406, in wrapper
    return func(self, *args, **kwargs)
           ^^^^^^^^^^^^^^^^^^^^^^^^^^^
  File "/home/airflow/.local/lib/python3.12/site-packages/airflow/operators/bash.py", line 249, in execute
    raise AirflowException(
airflow.exceptions.AirflowException: Bash command failed. The command returned a non-zero exit code 2.
[2024-10-13T23:09:16.074+0000] {local_task_job_runner.py:266} INFO - Task exited with return code 1
[2024-10-13T23:09:16.104+0000] {taskinstance.py:3900} INFO - 0 downstream tasks scheduled from follow-on schedule check
[2024-10-13T23:09:16.120+0000] {local_task_job_runner.py:245} INFO - ::endgroup::
