[2024-10-13T23:09:06.319+0000] {local_task_job_runner.py:123} INFO - ::group::Pre task execution logs
[2024-10-13T23:09:06.348+0000] {taskinstance.py:2612} INFO - Dependencies all met for dep_context=non-requeueable deps ti=<TaskInstance: adewunmi.execute_bash_command manual__2024-10-13T23:05:58.528395+00:00 [queued]>
[2024-10-13T23:09:06.362+0000] {taskinstance.py:2612} INFO - Dependencies all met for dep_context=requeueable deps ti=<TaskInstance: adewunmi.execute_bash_command manual__2024-10-13T23:05:58.528395+00:00 [queued]>
[2024-10-13T23:09:06.363+0000] {taskinstance.py:2865} INFO - Starting attempt 3 of 4
[2024-10-13T23:09:06.387+0000] {taskinstance.py:2888} INFO - Executing <Task(BashOperator): execute_bash_command> on 2024-10-13 23:05:58.528395+00:00
[2024-10-13T23:09:06.395+0000] {warnings.py:112} WARNING - /home/***/.local/lib/python3.12/site-packages/***/task/task_runner/standard_task_runner.py:70: DeprecationWarning: This process (pid=305) is multi-threaded, use of fork() may lead to deadlocks in the child.
  pid = os.fork()

[2024-10-13T23:09:06.397+0000] {standard_task_runner.py:72} INFO - Started process 306 to run task
[2024-10-13T23:09:06.398+0000] {standard_task_runner.py:104} INFO - Running: ['***', 'tasks', 'run', 'adewunmi', 'execute_bash_command', 'manual__2024-10-13T23:05:58.528395+00:00', '--job-id', '10', '--raw', '--subdir', 'DAGS_FOLDER/email.py', '--cfg-path', '/tmp/tmp0ys8rm_7']
[2024-10-13T23:09:06.400+0000] {standard_task_runner.py:105} INFO - Job 10: Subtask execute_bash_command
[2024-10-13T23:09:06.474+0000] {task_command.py:467} INFO - Running <TaskInstance: adewunmi.execute_bash_command manual__2024-10-13T23:05:58.528395+00:00 [running]> on host 1b4cad12ae67
[2024-10-13T23:09:06.597+0000] {taskinstance.py:3131} INFO - Exporting env vars: AIRFLOW_CTX_DAG_OWNER='adewunmi' AIRFLOW_CTX_DAG_ID='adewunmi' AIRFLOW_CTX_TASK_ID='execute_bash_command' AIRFLOW_CTX_EXECUTION_DATE='2024-10-13T23:05:58.528395+00:00' AIRFLOW_CTX_TRY_NUMBER='3' AIRFLOW_CTX_DAG_RUN_ID='manual__2024-10-13T23:05:58.528395+00:00'
[2024-10-13T23:09:06.599+0000] {taskinstance.py:731} INFO - ::endgroup::
[2024-10-13T23:09:06.622+0000] {subprocess.py:63} INFO - Tmp dir root location: /tmp
[2024-10-13T23:09:06.623+0000] {subprocess.py:75} INFO - Running command: ['/usr/bin/bash', '-c', 'echo "Hello, world!']
[2024-10-13T23:09:06.636+0000] {subprocess.py:86} INFO - Output:
[2024-10-13T23:09:06.638+0000] {subprocess.py:93} INFO - /usr/bin/bash: -c: line 1: unexpected EOF while looking for matching `"'
[2024-10-13T23:09:06.639+0000] {subprocess.py:97} INFO - Command exited with return code 2
[2024-10-13T23:09:06.654+0000] {taskinstance.py:3310} ERROR - Task failed with exception
Traceback (most recent call last):
  File "/home/airflow/.local/lib/python3.12/site-packages/airflow/models/taskinstance.py", line 767, in _execute_task
    result = _execute_callable(context=context, **execute_callable_kwargs)
             ^^^^^^^^^^^^^^^^^^^^^^^^^^^^^^^^^^^^^^^^^^^^^^^^^^^^^^^^^^^^^
  File "/home/airflow/.local/lib/python3.12/site-packages/airflow/models/taskinstance.py", line 733, in _execute_callable
    return ExecutionCallableRunner(
           ^^^^^^^^^^^^^^^^^^^^^^^^
  File "/home/airflow/.local/lib/python3.12/site-packages/airflow/utils/operator_helpers.py", line 252, in run
    return self.func(*args, **kwargs)
           ^^^^^^^^^^^^^^^^^^^^^^^^^^
  File "/home/airflow/.local/lib/python3.12/site-packages/airflow/models/baseoperator.py", line 406, in wrapper
    return func(self, *args, **kwargs)
           ^^^^^^^^^^^^^^^^^^^^^^^^^^^
  File "/home/airflow/.local/lib/python3.12/site-packages/airflow/operators/bash.py", line 249, in execute
    raise AirflowException(
airflow.exceptions.AirflowException: Bash command failed. The command returned a non-zero exit code 2.
[2024-10-13T23:09:06.665+0000] {taskinstance.py:1225} INFO - Marking task as UP_FOR_RETRY. dag_id=adewunmi, task_id=execute_bash_command, run_id=manual__2024-10-13T23:05:58.528395+00:00, execution_date=20241013T230558, start_date=20241013T230906, end_date=20241013T230906
[2024-10-13T23:09:06.694+0000] {taskinstance.py:340} INFO - ::group::Post task execution logs
[2024-10-13T23:09:06.695+0000] {standard_task_runner.py:124} ERROR - Failed to execute job 10 for task execute_bash_command (Bash command failed. The command returned a non-zero exit code 2.; 306)
Traceback (most recent call last):
  File "/home/airflow/.local/lib/python3.12/site-packages/airflow/task/task_runner/standard_task_runner.py", line 117, in _start_by_fork
    ret = args.func(args, dag=self.dag)
          ^^^^^^^^^^^^^^^^^^^^^^^^^^^^^
  File "/home/airflow/.local/lib/python3.12/site-packages/airflow/cli/cli_config.py", line 49, in command
    return func(*args, **kwargs)
           ^^^^^^^^^^^^^^^^^^^^^
  File "/home/airflow/.local/lib/python3.12/site-packages/airflow/utils/cli.py", line 115, in wrapper
    return f(*args, **kwargs)
           ^^^^^^^^^^^^^^^^^^
  File "/home/airflow/.local/lib/python3.12/site-packages/airflow/cli/commands/task_command.py", line 483, in task_run
    task_return_code = _run_task_by_selected_method(args, _dag, ti)
                       ^^^^^^^^^^^^^^^^^^^^^^^^^^^^^^^^^^^^^^^^^^^^
  File "/home/airflow/.local/lib/python3.12/site-packages/airflow/cli/commands/task_command.py", line 256, in _run_task_by_selected_method
    return _run_raw_task(args, ti)
           ^^^^^^^^^^^^^^^^^^^^^^^
  File "/home/airflow/.local/lib/python3.12/site-packages/airflow/cli/commands/task_command.py", line 341, in _run_raw_task
    return ti._run_raw_task(
           ^^^^^^^^^^^^^^^^^
  File "/home/airflow/.local/lib/python3.12/site-packages/airflow/utils/session.py", line 97, in wrapper
    return func(*args, session=session, **kwargs)
           ^^^^^^^^^^^^^^^^^^^^^^^^^^^^^^^^^^^^^^
  File "/home/airflow/.local/lib/python3.12/site-packages/airflow/models/taskinstance.py", line 3004, in _run_raw_task
    return _run_raw_task(
           ^^^^^^^^^^^^^^
  File "/home/airflow/.local/lib/python3.12/site-packages/airflow/models/taskinstance.py", line 273, in _run_raw_task
    TaskInstance._execute_task_with_callbacks(
  File "/home/airflow/.local/lib/python3.12/site-packages/airflow/models/taskinstance.py", line 3158, in _execute_task_with_callbacks
    result = self._execute_task(context, task_orig)
             ^^^^^^^^^^^^^^^^^^^^^^^^^^^^^^^^^^^^^^
  File "/home/airflow/.local/lib/python3.12/site-packages/airflow/models/taskinstance.py", line 3182, in _execute_task
    return _execute_task(self, context, task_orig)
           ^^^^^^^^^^^^^^^^^^^^^^^^^^^^^^^^^^^^^^^
  File "/home/airflow/.local/lib/python3.12/site-packages/airflow/models/taskinstance.py", line 767, in _execute_task
    result = _execute_callable(context=context, **execute_callable_kwargs)
             ^^^^^^^^^^^^^^^^^^^^^^^^^^^^^^^^^^^^^^^^^^^^^^^^^^^^^^^^^^^^^
  File "/home/airflow/.local/lib/python3.12/site-packages/airflow/models/taskinstance.py", line 733, in _execute_callable
    return ExecutionCallableRunner(
           ^^^^^^^^^^^^^^^^^^^^^^^^
  File "/home/airflow/.local/lib/python3.12/site-packages/airflow/utils/operator_helpers.py", line 252, in run
    return self.func(*args, **kwargs)
           ^^^^^^^^^^^^^^^^^^^^^^^^^^
  File "/home/airflow/.local/lib/python3.12/site-packages/airflow/models/baseoperator.py", line 406, in wrapper
    return func(self, *args, **kwargs)
           ^^^^^^^^^^^^^^^^^^^^^^^^^^^
  File "/home/airflow/.local/lib/python3.12/site-packages/airflow/operators/bash.py", line 249, in execute
    raise AirflowException(
airflow.exceptions.AirflowException: Bash command failed. The command returned a non-zero exit code 2.
[2024-10-13T23:09:06.734+0000] {local_task_job_runner.py:266} INFO - Task exited with return code 1
[2024-10-13T23:09:06.762+0000] {taskinstance.py:3900} INFO - 0 downstream tasks scheduled from follow-on schedule check
[2024-10-13T23:09:06.766+0000] {local_task_job_runner.py:245} INFO - ::endgroup::
