[2024-11-25T20:40:44.254+0000] {local_task_job_runner.py:123} INFO - ::group::Pre task execution logs
[2024-11-25T20:40:44.278+0000] {taskinstance.py:2612} INFO - Dependencies all met for dep_context=non-requeueable deps ti=<TaskInstance: ckckc.get_request_api manual__2024-11-25T20:26:09.196196+00:00 [queued]>
[2024-11-25T20:40:44.291+0000] {taskinstance.py:2612} INFO - Dependencies all met for dep_context=requeueable deps ti=<TaskInstance: ckckc.get_request_api manual__2024-11-25T20:26:09.196196+00:00 [queued]>
[2024-11-25T20:40:44.292+0000] {taskinstance.py:2865} INFO - Starting attempt 6 of 6
[2024-11-25T20:40:44.331+0000] {taskinstance.py:2888} INFO - Executing <Task(PythonOperator): get_request_api> on 2024-11-25 20:26:09.196196+00:00
[2024-11-25T20:40:44.340+0000] {warnings.py:112} WARNING - /home/***/.local/lib/python3.12/site-packages/***/task/task_runner/standard_task_runner.py:70: DeprecationWarning: This process (pid=314) is multi-threaded, use of fork() may lead to deadlocks in the child.
  pid = os.fork()

[2024-11-25T20:40:44.342+0000] {standard_task_runner.py:72} INFO - Started process 316 to run task
[2024-11-25T20:40:44.343+0000] {standard_task_runner.py:104} INFO - Running: ['***', 'tasks', 'run', 'ckckc', 'get_request_api', 'manual__2024-11-25T20:26:09.196196+00:00', '--job-id', '140', '--raw', '--subdir', 'DAGS_FOLDER/capstone_***/refractor_code_dag.py', '--cfg-path', '/tmp/tmp2q8nwrz3']
[2024-11-25T20:40:44.347+0000] {standard_task_runner.py:105} INFO - Job 140: Subtask get_request_api
[2024-11-25T20:40:44.434+0000] {task_command.py:467} INFO - Running <TaskInstance: ckckc.get_request_api manual__2024-11-25T20:26:09.196196+00:00 [running]> on host 4c68e6e733db
[2024-11-25T20:40:44.587+0000] {taskinstance.py:3131} INFO - Exporting env vars: AIRFLOW_CTX_DAG_OWNER='adewunmi' AIRFLOW_CTX_DAG_ID='ckckc' AIRFLOW_CTX_TASK_ID='get_request_api' AIRFLOW_CTX_EXECUTION_DATE='2024-11-25T20:26:09.196196+00:00' AIRFLOW_CTX_TRY_NUMBER='6' AIRFLOW_CTX_DAG_RUN_ID='manual__2024-11-25T20:26:09.196196+00:00'
[2024-11-25T20:40:44.590+0000] {taskinstance.py:731} INFO - ::endgroup::
[2024-11-25T20:40:44.617+0000] {extract_load_to_s3.py:20} INFO - GET request initiating
[2024-11-25T20:40:45.637+0000] {taskinstance.py:3310} ERROR - Task failed with exception
Traceback (most recent call last):
  File "/home/airflow/.local/lib/python3.12/site-packages/urllib3/response.py", line 748, in _error_catcher
    yield
  File "/home/airflow/.local/lib/python3.12/site-packages/urllib3/response.py", line 894, in _raw_read
    raise IncompleteRead(self._fp_bytes_read, self.length_remaining)
urllib3.exceptions.IncompleteRead: IncompleteRead(32534 bytes read, 138644 more expected)

The above exception was the direct cause of the following exception:

Traceback (most recent call last):
  File "/home/airflow/.local/lib/python3.12/site-packages/requests/models.py", line 820, in generate
    yield from self.raw.stream(chunk_size, decode_content=True)
  File "/home/airflow/.local/lib/python3.12/site-packages/urllib3/response.py", line 1060, in stream
    data = self.read(amt=amt, decode_content=decode_content)
           ^^^^^^^^^^^^^^^^^^^^^^^^^^^^^^^^^^^^^^^^^^^^^^^^^
  File "/home/airflow/.local/lib/python3.12/site-packages/urllib3/response.py", line 949, in read
    data = self._raw_read(amt)
           ^^^^^^^^^^^^^^^^^^^
  File "/home/airflow/.local/lib/python3.12/site-packages/urllib3/response.py", line 872, in _raw_read
    with self._error_catcher():
  File "/usr/local/lib/python3.12/contextlib.py", line 158, in __exit__
    self.gen.throw(value)
  File "/home/airflow/.local/lib/python3.12/site-packages/urllib3/response.py", line 772, in _error_catcher
    raise ProtocolError(arg, e) from e
urllib3.exceptions.ProtocolError: ('Connection broken: IncompleteRead(32534 bytes read, 138644 more expected)', IncompleteRead(32534 bytes read, 138644 more expected))

During handling of the above exception, another exception occurred:

Traceback (most recent call last):
  File "/opt/airflow/dags/capstone_airflow/function/extract_load_to_s3.py", line 21, in country_api_request
    get_api = requests.get(url)
              ^^^^^^^^^^^^^^^^^
  File "/home/airflow/.local/lib/python3.12/site-packages/requests/api.py", line 73, in get
    return request("get", url, params=params, **kwargs)
           ^^^^^^^^^^^^^^^^^^^^^^^^^^^^^^^^^^^^^^^^^^^^
  File "/home/airflow/.local/lib/python3.12/site-packages/requests/api.py", line 59, in request
    return session.request(method=method, url=url, **kwargs)
           ^^^^^^^^^^^^^^^^^^^^^^^^^^^^^^^^^^^^^^^^^^^^^^^^^
  File "/home/airflow/.local/lib/python3.12/site-packages/requests/sessions.py", line 589, in request
    resp = self.send(prep, **send_kwargs)
           ^^^^^^^^^^^^^^^^^^^^^^^^^^^^^^
  File "/home/airflow/.local/lib/python3.12/site-packages/requests/sessions.py", line 746, in send
    r.content
  File "/home/airflow/.local/lib/python3.12/site-packages/requests/models.py", line 902, in content
    self._content = b"".join(self.iter_content(CONTENT_CHUNK_SIZE)) or b""
                    ^^^^^^^^^^^^^^^^^^^^^^^^^^^^^^^^^^^^^^^^^^^^^^^
  File "/home/airflow/.local/lib/python3.12/site-packages/requests/models.py", line 822, in generate
    raise ChunkedEncodingError(e)
requests.exceptions.ChunkedEncodingError: ('Connection broken: IncompleteRead(32534 bytes read, 138644 more expected)', IncompleteRead(32534 bytes read, 138644 more expected))

During handling of the above exception, another exception occurred:

Traceback (most recent call last):
  File "/home/airflow/.local/lib/python3.12/site-packages/airflow/models/taskinstance.py", line 767, in _execute_task
    result = _execute_callable(context=context, **execute_callable_kwargs)
             ^^^^^^^^^^^^^^^^^^^^^^^^^^^^^^^^^^^^^^^^^^^^^^^^^^^^^^^^^^^^^
  File "/home/airflow/.local/lib/python3.12/site-packages/airflow/models/taskinstance.py", line 733, in _execute_callable
    return ExecutionCallableRunner(
           ^^^^^^^^^^^^^^^^^^^^^^^^
  File "/home/airflow/.local/lib/python3.12/site-packages/airflow/utils/operator_helpers.py", line 252, in run
    return self.func(*args, **kwargs)
           ^^^^^^^^^^^^^^^^^^^^^^^^^^
  File "/home/airflow/.local/lib/python3.12/site-packages/airflow/models/baseoperator.py", line 406, in wrapper
    return func(self, *args, **kwargs)
           ^^^^^^^^^^^^^^^^^^^^^^^^^^^
  File "/home/airflow/.local/lib/python3.12/site-packages/airflow/operators/python.py", line 238, in execute
    return_value = self.execute_callable()
                   ^^^^^^^^^^^^^^^^^^^^^^^
  File "/home/airflow/.local/lib/python3.12/site-packages/airflow/operators/python.py", line 256, in execute_callable
    return runner.run(*self.op_args, **self.op_kwargs)
           ^^^^^^^^^^^^^^^^^^^^^^^^^^^^^^^^^^^^^^^^^^^
  File "/home/airflow/.local/lib/python3.12/site-packages/airflow/utils/operator_helpers.py", line 252, in run
    return self.func(*args, **kwargs)
           ^^^^^^^^^^^^^^^^^^^^^^^^^^
  File "/opt/airflow/dags/capstone_airflow/function/extract_load_to_s3.py", line 50, in country_api_request
    raise Exception(f"An unexpected error occurred: {e}")
Exception: An unexpected error occurred: ('Connection broken: IncompleteRead(32534 bytes read, 138644 more expected)', IncompleteRead(32534 bytes read, 138644 more expected))
[2024-11-25T20:40:45.694+0000] {taskinstance.py:1225} INFO - Marking task as FAILED. dag_id=ckckc, task_id=get_request_api, run_id=manual__2024-11-25T20:26:09.196196+00:00, execution_date=20241125T202609, start_date=20241125T204044, end_date=20241125T204045
[2024-11-25T20:40:45.701+0000] {taskinstance.py:1563} INFO - Executing callback at index 0: task_fail_alert
[2024-11-25T20:40:45.737+0000] {logging_mixin.py:190} INFO - {'conf': <***.configuration.AirflowConfigParser object at 0x7f8d77884cb0>, 'dag': <DAG: ckckc>, 'dag_run': <DagRun ckckc @ 2024-11-25 20:26:09.196196+00:00: manual__2024-11-25T20:26:09.196196+00:00, state:running, queued_at: 2024-11-25 20:26:09.262149+00:00. externally triggered: True>, 'data_interval_end': DateTime(2024, 11, 25, 20, 26, 9, 196196, tzinfo=Timezone('UTC')), 'data_interval_start': DateTime(2024, 11, 25, 20, 26, 9, 196196, tzinfo=Timezone('UTC')), 'outlet_events': <***.utils.context.OutletEventAccessors object at 0x7f8d56cdb1d0>, 'ds': '2024-11-25', 'ds_nodash': '20241125', 'execution_date': DateTime(2024, 11, 25, 20, 26, 9, 196196, tzinfo=Timezone('UTC')), 'expanded_ti_count': None, 'inlets': [], 'inlet_events': InletEventsAccessors(_inlets=[], _datasets={}, _dataset_aliases={}, _session=<sqlalchemy.orm.session.Session object at 0x7f8d74ef5970>), 'logical_date': DateTime(2024, 11, 25, 20, 26, 9, 196196, tzinfo=Timezone('UTC')), 'macros': <module '***.macros' from '/home/***/.local/lib/python3.12/site-packages/***/macros/__init__.py'>, 'map_index_template': None, 'next_ds': '2024-11-25', 'next_ds_nodash': '20241125', 'next_execution_date': DateTime(2024, 11, 25, 20, 26, 9, 196196, tzinfo=Timezone('UTC')), 'outlets': [], 'params': {}, 'prev_data_interval_start_success': None, 'prev_data_interval_end_success': None, 'prev_ds': '2024-11-25', 'prev_ds_nodash': '20241125', 'prev_execution_date': DateTime(2024, 11, 25, 20, 26, 9, 196196, tzinfo=Timezone('UTC')), 'prev_execution_date_success': None, 'prev_start_date_success': None, 'prev_end_date_success': None, 'run_id': 'manual__2024-11-25T20:26:09.196196+00:00', 'task': <Task(PythonOperator): get_request_api>, 'task_instance': <TaskInstance: ckckc.get_request_api manual__2024-11-25T20:26:09.196196+00:00 [failed]>, 'task_instance_key_str': 'ckckc__get_request_api__20241125', 'test_mode': False, 'ti': <TaskInstance: ckckc.get_request_api manual__2024-11-25T20:26:09.196196+00:00 [failed]>, 'tomorrow_ds': '2024-11-26', 'tomorrow_ds_nodash': '20241126', 'triggering_dataset_events': <Proxy at 0x7f8d56d02680 with factory <function _get_template_context.<locals>.get_triggering_events at 0x7f8d56cc3100>>, 'ts': '2024-11-25T20:26:09.196196+00:00', 'ts_nodash': '20241125T202609', 'ts_nodash_with_tz': '20241125T202609.196196+0000', 'var': {'json': None, 'value': None}, 'conn': None, 'yesterday_ds': '2024-11-24', 'yesterday_ds_nodash': '20241124', 'templates_dict': None, 'exception': Exception("An unexpected error occurred: ('Connection broken: IncompleteRead(32534 bytes read, 138644 more expected)', IncompleteRead(32534 bytes read, 138644 more expected))")}
[2024-11-25T20:40:49.527+0000] {logging_mixin.py:190} INFO - Email Sent Successfully
[2024-11-25T20:40:49.690+0000] {taskinstance.py:340} INFO - ::group::Post task execution logs
[2024-11-25T20:40:49.692+0000] {standard_task_runner.py:124} ERROR - Failed to execute job 140 for task get_request_api (An unexpected error occurred: ('Connection broken: IncompleteRead(32534 bytes read, 138644 more expected)', IncompleteRead(32534 bytes read, 138644 more expected)); 316)
Traceback (most recent call last):
  File "/home/airflow/.local/lib/python3.12/site-packages/urllib3/response.py", line 748, in _error_catcher
    yield
  File "/home/airflow/.local/lib/python3.12/site-packages/urllib3/response.py", line 894, in _raw_read
    raise IncompleteRead(self._fp_bytes_read, self.length_remaining)
urllib3.exceptions.IncompleteRead: IncompleteRead(32534 bytes read, 138644 more expected)

The above exception was the direct cause of the following exception:

Traceback (most recent call last):
  File "/home/airflow/.local/lib/python3.12/site-packages/requests/models.py", line 820, in generate
    yield from self.raw.stream(chunk_size, decode_content=True)
  File "/home/airflow/.local/lib/python3.12/site-packages/urllib3/response.py", line 1060, in stream
    data = self.read(amt=amt, decode_content=decode_content)
           ^^^^^^^^^^^^^^^^^^^^^^^^^^^^^^^^^^^^^^^^^^^^^^^^^
  File "/home/airflow/.local/lib/python3.12/site-packages/urllib3/response.py", line 949, in read
    data = self._raw_read(amt)
           ^^^^^^^^^^^^^^^^^^^
  File "/home/airflow/.local/lib/python3.12/site-packages/urllib3/response.py", line 872, in _raw_read
    with self._error_catcher():
  File "/usr/local/lib/python3.12/contextlib.py", line 158, in __exit__
    self.gen.throw(value)
  File "/home/airflow/.local/lib/python3.12/site-packages/urllib3/response.py", line 772, in _error_catcher
    raise ProtocolError(arg, e) from e
urllib3.exceptions.ProtocolError: ('Connection broken: IncompleteRead(32534 bytes read, 138644 more expected)', IncompleteRead(32534 bytes read, 138644 more expected))

During handling of the above exception, another exception occurred:

Traceback (most recent call last):
  File "/opt/airflow/dags/capstone_airflow/function/extract_load_to_s3.py", line 21, in country_api_request
    get_api = requests.get(url)
              ^^^^^^^^^^^^^^^^^
  File "/home/airflow/.local/lib/python3.12/site-packages/requests/api.py", line 73, in get
    return request("get", url, params=params, **kwargs)
           ^^^^^^^^^^^^^^^^^^^^^^^^^^^^^^^^^^^^^^^^^^^^
  File "/home/airflow/.local/lib/python3.12/site-packages/requests/api.py", line 59, in request
    return session.request(method=method, url=url, **kwargs)
           ^^^^^^^^^^^^^^^^^^^^^^^^^^^^^^^^^^^^^^^^^^^^^^^^^
  File "/home/airflow/.local/lib/python3.12/site-packages/requests/sessions.py", line 589, in request
    resp = self.send(prep, **send_kwargs)
           ^^^^^^^^^^^^^^^^^^^^^^^^^^^^^^
  File "/home/airflow/.local/lib/python3.12/site-packages/requests/sessions.py", line 746, in send
    r.content
  File "/home/airflow/.local/lib/python3.12/site-packages/requests/models.py", line 902, in content
    self._content = b"".join(self.iter_content(CONTENT_CHUNK_SIZE)) or b""
                    ^^^^^^^^^^^^^^^^^^^^^^^^^^^^^^^^^^^^^^^^^^^^^^^
  File "/home/airflow/.local/lib/python3.12/site-packages/requests/models.py", line 822, in generate
    raise ChunkedEncodingError(e)
requests.exceptions.ChunkedEncodingError: ('Connection broken: IncompleteRead(32534 bytes read, 138644 more expected)', IncompleteRead(32534 bytes read, 138644 more expected))

During handling of the above exception, another exception occurred:

Traceback (most recent call last):
  File "/home/airflow/.local/lib/python3.12/site-packages/airflow/task/task_runner/standard_task_runner.py", line 117, in _start_by_fork
    ret = args.func(args, dag=self.dag)
          ^^^^^^^^^^^^^^^^^^^^^^^^^^^^^
  File "/home/airflow/.local/lib/python3.12/site-packages/airflow/cli/cli_config.py", line 49, in command
    return func(*args, **kwargs)
           ^^^^^^^^^^^^^^^^^^^^^
  File "/home/airflow/.local/lib/python3.12/site-packages/airflow/utils/cli.py", line 115, in wrapper
    return f(*args, **kwargs)
           ^^^^^^^^^^^^^^^^^^
  File "/home/airflow/.local/lib/python3.12/site-packages/airflow/cli/commands/task_command.py", line 483, in task_run
    task_return_code = _run_task_by_selected_method(args, _dag, ti)
                       ^^^^^^^^^^^^^^^^^^^^^^^^^^^^^^^^^^^^^^^^^^^^
  File "/home/airflow/.local/lib/python3.12/site-packages/airflow/cli/commands/task_command.py", line 256, in _run_task_by_selected_method
    return _run_raw_task(args, ti)
           ^^^^^^^^^^^^^^^^^^^^^^^
  File "/home/airflow/.local/lib/python3.12/site-packages/airflow/cli/commands/task_command.py", line 341, in _run_raw_task
    return ti._run_raw_task(
           ^^^^^^^^^^^^^^^^^
  File "/home/airflow/.local/lib/python3.12/site-packages/airflow/utils/session.py", line 97, in wrapper
    return func(*args, session=session, **kwargs)
           ^^^^^^^^^^^^^^^^^^^^^^^^^^^^^^^^^^^^^^
  File "/home/airflow/.local/lib/python3.12/site-packages/airflow/models/taskinstance.py", line 3004, in _run_raw_task
    return _run_raw_task(
           ^^^^^^^^^^^^^^
  File "/home/airflow/.local/lib/python3.12/site-packages/airflow/models/taskinstance.py", line 273, in _run_raw_task
    TaskInstance._execute_task_with_callbacks(
  File "/home/airflow/.local/lib/python3.12/site-packages/airflow/models/taskinstance.py", line 3158, in _execute_task_with_callbacks
    result = self._execute_task(context, task_orig)
             ^^^^^^^^^^^^^^^^^^^^^^^^^^^^^^^^^^^^^^
  File "/home/airflow/.local/lib/python3.12/site-packages/airflow/models/taskinstance.py", line 3182, in _execute_task
    return _execute_task(self, context, task_orig)
           ^^^^^^^^^^^^^^^^^^^^^^^^^^^^^^^^^^^^^^^
  File "/home/airflow/.local/lib/python3.12/site-packages/airflow/models/taskinstance.py", line 767, in _execute_task
    result = _execute_callable(context=context, **execute_callable_kwargs)
             ^^^^^^^^^^^^^^^^^^^^^^^^^^^^^^^^^^^^^^^^^^^^^^^^^^^^^^^^^^^^^
  File "/home/airflow/.local/lib/python3.12/site-packages/airflow/models/taskinstance.py", line 733, in _execute_callable
    return ExecutionCallableRunner(
           ^^^^^^^^^^^^^^^^^^^^^^^^
  File "/home/airflow/.local/lib/python3.12/site-packages/airflow/utils/operator_helpers.py", line 252, in run
    return self.func(*args, **kwargs)
           ^^^^^^^^^^^^^^^^^^^^^^^^^^
  File "/home/airflow/.local/lib/python3.12/site-packages/airflow/models/baseoperator.py", line 406, in wrapper
    return func(self, *args, **kwargs)
           ^^^^^^^^^^^^^^^^^^^^^^^^^^^
  File "/home/airflow/.local/lib/python3.12/site-packages/airflow/operators/python.py", line 238, in execute
    return_value = self.execute_callable()
                   ^^^^^^^^^^^^^^^^^^^^^^^
  File "/home/airflow/.local/lib/python3.12/site-packages/airflow/operators/python.py", line 256, in execute_callable
    return runner.run(*self.op_args, **self.op_kwargs)
           ^^^^^^^^^^^^^^^^^^^^^^^^^^^^^^^^^^^^^^^^^^^
  File "/home/airflow/.local/lib/python3.12/site-packages/airflow/utils/operator_helpers.py", line 252, in run
    return self.func(*args, **kwargs)
           ^^^^^^^^^^^^^^^^^^^^^^^^^^
  File "/opt/airflow/dags/capstone_airflow/function/extract_load_to_s3.py", line 50, in country_api_request
    raise Exception(f"An unexpected error occurred: {e}")
Exception: An unexpected error occurred: ('Connection broken: IncompleteRead(32534 bytes read, 138644 more expected)', IncompleteRead(32534 bytes read, 138644 more expected))
[2024-11-25T20:40:49.734+0000] {local_task_job_runner.py:266} INFO - Task exited with return code 1
[2024-11-25T20:40:49.772+0000] {taskinstance.py:3900} INFO - 0 downstream tasks scheduled from follow-on schedule check
[2024-11-25T20:40:49.797+0000] {local_task_job_runner.py:245} INFO - ::endgroup::
