[2024-10-19T16:56:14.257+0000] {local_task_job_runner.py:123} INFO - ::group::Pre task execution logs
[2024-10-19T16:56:14.281+0000] {taskinstance.py:2612} INFO - Dependencies all met for dep_context=non-requeueable deps ti=<TaskInstance: postgres_to_s3.load_to_s3 manual__2024-10-19T16:44:14.509632+00:00 [queued]>
[2024-10-19T16:56:14.297+0000] {taskinstance.py:2612} INFO - Dependencies all met for dep_context=requeueable deps ti=<TaskInstance: postgres_to_s3.load_to_s3 manual__2024-10-19T16:44:14.509632+00:00 [queued]>
[2024-10-19T16:56:14.298+0000] {taskinstance.py:2865} INFO - Starting attempt 2 of 2
[2024-10-19T16:56:14.328+0000] {taskinstance.py:2888} INFO - Executing <Task(PythonOperator): load_to_s3> on 2024-10-19 16:44:14.509632+00:00
[2024-10-19T16:56:14.338+0000] {warnings.py:112} WARNING - /home/***/.local/lib/python3.12/site-packages/***/task/task_runner/standard_task_runner.py:70: DeprecationWarning: This process (pid=1550) is multi-threaded, use of fork() may lead to deadlocks in the child.
  pid = os.fork()

[2024-10-19T16:56:14.340+0000] {standard_task_runner.py:72} INFO - Started process 1552 to run task
[2024-10-19T16:56:14.340+0000] {standard_task_runner.py:104} INFO - Running: ['***', 'tasks', 'run', 'postgres_to_s3', 'load_to_s3', 'manual__2024-10-19T16:44:14.509632+00:00', '--job-id', '40', '--raw', '--subdir', 'DAGS_FOLDER/prod.py', '--cfg-path', '/tmp/tmpobgjo_fp']
[2024-10-19T16:56:14.343+0000] {standard_task_runner.py:105} INFO - Job 40: Subtask load_to_s3
[2024-10-19T16:56:14.433+0000] {task_command.py:467} INFO - Running <TaskInstance: postgres_to_s3.load_to_s3 manual__2024-10-19T16:44:14.509632+00:00 [running]> on host 533638d20908
[2024-10-19T16:56:14.564+0000] {taskinstance.py:3131} INFO - Exporting env vars: AIRFLOW_CTX_DAG_OWNER='protectorate' AIRFLOW_CTX_DAG_ID='postgres_to_s3' AIRFLOW_CTX_TASK_ID='load_to_s3' AIRFLOW_CTX_EXECUTION_DATE='2024-10-19T16:44:14.509632+00:00' AIRFLOW_CTX_TRY_NUMBER='2' AIRFLOW_CTX_DAG_RUN_ID='manual__2024-10-19T16:44:14.509632+00:00'
[2024-10-19T16:56:14.565+0000] {taskinstance.py:731} INFO - ::endgroup::
[2024-10-19T16:56:14.619+0000] {base.py:84} INFO - Retrieving connection 'post_s3'
[2024-10-19T16:56:14.636+0000] {base.py:84} INFO - Retrieving connection 'post_s3'
[2024-10-19T16:56:14.765+0000] {taskinstance.py:3310} ERROR - Task failed with exception
Traceback (most recent call last):
  File "/home/airflow/.local/lib/python3.12/site-packages/sqlalchemy/engine/base.py", line 1890, in _execute_context
    self.dialect.do_executemany(
  File "/home/airflow/.local/lib/python3.12/site-packages/sqlalchemy/dialects/postgresql/psycopg2.py", line 982, in do_executemany
    context._psycopg2_fetched_rows = xtras.execute_values(
                                     ^^^^^^^^^^^^^^^^^^^^^
  File "/home/airflow/.local/lib/python3.12/site-packages/psycopg2/extras.py", line 1299, in execute_values
    cur.execute(b''.join(parts))
psycopg2.errors.UndefinedColumn: column " page_title" of relation "wiki_file" does not exist
LINE 1: INSERT INTO wiki_file (domain_name, " page_title", " view_co...
                                            ^


The above exception was the direct cause of the following exception:

Traceback (most recent call last):
  File "/home/airflow/.local/lib/python3.12/site-packages/airflow/models/taskinstance.py", line 767, in _execute_task
    result = _execute_callable(context=context, **execute_callable_kwargs)
             ^^^^^^^^^^^^^^^^^^^^^^^^^^^^^^^^^^^^^^^^^^^^^^^^^^^^^^^^^^^^^
  File "/home/airflow/.local/lib/python3.12/site-packages/airflow/models/taskinstance.py", line 733, in _execute_callable
    return ExecutionCallableRunner(
           ^^^^^^^^^^^^^^^^^^^^^^^^
  File "/home/airflow/.local/lib/python3.12/site-packages/airflow/utils/operator_helpers.py", line 252, in run
    return self.func(*args, **kwargs)
           ^^^^^^^^^^^^^^^^^^^^^^^^^^
  File "/home/airflow/.local/lib/python3.12/site-packages/airflow/models/baseoperator.py", line 406, in wrapper
    return func(self, *args, **kwargs)
           ^^^^^^^^^^^^^^^^^^^^^^^^^^^
  File "/home/airflow/.local/lib/python3.12/site-packages/airflow/operators/python.py", line 238, in execute
    return_value = self.execute_callable()
                   ^^^^^^^^^^^^^^^^^^^^^^^
  File "/home/airflow/.local/lib/python3.12/site-packages/airflow/operators/python.py", line 256, in execute_callable
    return runner.run(*self.op_args, **self.op_kwargs)
           ^^^^^^^^^^^^^^^^^^^^^^^^^^^^^^^^^^^^^^^^^^^
  File "/home/airflow/.local/lib/python3.12/site-packages/airflow/utils/operator_helpers.py", line 252, in run
    return self.func(*args, **kwargs)
           ^^^^^^^^^^^^^^^^^^^^^^^^^^
  File "/opt/airflow/dags/prod.py", line 48, in load_csv_to_database
    df.to_sql('wiki_file', engine, if_exists='append', index=False)
  File "/home/airflow/.local/lib/python3.12/site-packages/pandas/util/_decorators.py", line 333, in wrapper
    return func(*args, **kwargs)
           ^^^^^^^^^^^^^^^^^^^^^
  File "/home/airflow/.local/lib/python3.12/site-packages/pandas/core/generic.py", line 3008, in to_sql
    return sql.to_sql(
           ^^^^^^^^^^^
  File "/home/airflow/.local/lib/python3.12/site-packages/pandas/io/sql.py", line 788, in to_sql
    return pandas_sql.to_sql(
           ^^^^^^^^^^^^^^^^^^
  File "/home/airflow/.local/lib/python3.12/site-packages/pandas/io/sql.py", line 1958, in to_sql
    total_inserted = sql_engine.insert_records(
                     ^^^^^^^^^^^^^^^^^^^^^^^^^^
  File "/home/airflow/.local/lib/python3.12/site-packages/pandas/io/sql.py", line 1507, in insert_records
    raise err
  File "/home/airflow/.local/lib/python3.12/site-packages/pandas/io/sql.py", line 1498, in insert_records
    return table.insert(chunksize=chunksize, method=method)
           ^^^^^^^^^^^^^^^^^^^^^^^^^^^^^^^^^^^^^^^^^^^^^^^^
  File "/home/airflow/.local/lib/python3.12/site-packages/pandas/io/sql.py", line 1059, in insert
    num_inserted = exec_insert(conn, keys, chunk_iter)
                   ^^^^^^^^^^^^^^^^^^^^^^^^^^^^^^^^^^^
  File "/home/airflow/.local/lib/python3.12/site-packages/pandas/io/sql.py", line 951, in _execute_insert
    result = conn.execute(self.table.insert(), data)
             ^^^^^^^^^^^^^^^^^^^^^^^^^^^^^^^^^^^^^^^
  File "/home/airflow/.local/lib/python3.12/site-packages/sqlalchemy/engine/base.py", line 1385, in execute
    return meth(self, multiparams, params, _EMPTY_EXECUTION_OPTS)
           ^^^^^^^^^^^^^^^^^^^^^^^^^^^^^^^^^^^^^^^^^^^^^^^^^^^^^^
  File "/home/airflow/.local/lib/python3.12/site-packages/sqlalchemy/sql/elements.py", line 334, in _execute_on_connection
    return connection._execute_clauseelement(
           ^^^^^^^^^^^^^^^^^^^^^^^^^^^^^^^^^^
  File "/home/airflow/.local/lib/python3.12/site-packages/sqlalchemy/engine/base.py", line 1577, in _execute_clauseelement
    ret = self._execute_context(
          ^^^^^^^^^^^^^^^^^^^^^^
  File "/home/airflow/.local/lib/python3.12/site-packages/sqlalchemy/engine/base.py", line 1953, in _execute_context
    self._handle_dbapi_exception(
  File "/home/airflow/.local/lib/python3.12/site-packages/sqlalchemy/engine/base.py", line 2134, in _handle_dbapi_exception
    util.raise_(
  File "/home/airflow/.local/lib/python3.12/site-packages/sqlalchemy/util/compat.py", line 211, in raise_
    raise exception
  File "/home/airflow/.local/lib/python3.12/site-packages/sqlalchemy/engine/base.py", line 1890, in _execute_context
    self.dialect.do_executemany(
  File "/home/airflow/.local/lib/python3.12/site-packages/sqlalchemy/dialects/postgresql/psycopg2.py", line 982, in do_executemany
    context._psycopg2_fetched_rows = xtras.execute_values(
                                     ^^^^^^^^^^^^^^^^^^^^^
  File "/home/airflow/.local/lib/python3.12/site-packages/psycopg2/extras.py", line 1299, in execute_values
    cur.execute(b''.join(parts))
sqlalchemy.exc.ProgrammingError: (psycopg2.errors.UndefinedColumn) column " page_title" of relation "wiki_file" does not exist
LINE 1: INSERT INTO wiki_file (domain_name, " page_title", " view_co...
                                            ^

[SQL: INSERT INTO wiki_file (domain_name, " page_title", " view_count", " size", " date", " hour") VALUES (%(domain_name)s, %(_page_title)s, %(_view_count)s, %(_size)s, %(_date)s, %(_hour)s)]
[parameters: ({'domain_name': 'ace.m', '_page_title': ' Facebook', '_view_count': 2, '_size': 0, '_date': ' 2024/10/19', '_hour': 14}, {'domain_name': 'af.m', '_page_title': ' Google_Chrome', '_view_count': 1, '_size': 0, '_date': ' 2024/10/19', '_hour': 14}, {'domain_name': 'als.m', '_page_title': ' Facebook', '_view_count': 2, '_size': 0, '_date': ' 2024/10/19', '_hour': 14}, {'domain_name': 'ar', '_page_title': ' ملف:2023_Facebook_icon.svg', '_view_count': 1, '_size': 0, '_date': ' 2024/10/19', '_hour': 14}, {'domain_name': 'ar', '_page_title': ' ملف:Facebook_Logo_(2019).png', '_view_count': 1, '_size': 0, '_date': ' 2024/10/19', '_hour': 14}, {'domain_name': 'ar', '_page_title': ' ملف:Facebook_logo_(square).png', '_view_count': 1, '_size': 0, '_date': ' 2024/10/19', '_hour': 14}, {'domain_name': 'ar', '_page_title': ' ملف:Juan_Gris_-_Portrait_of_Pablo_Picasso_-_Google_Art_Project.jpg', '_view_count': 1, '_size': 0, '_date': ' 2024/10/19', '_hour': 14}, {'domain_name': 'ar', '_page_title': ' ملف:Microsoft_Store.svg', '_view_count': 1, '_size': 0, '_date': ' 2024/10/19', '_hour': 14}  ... displaying 10 of 5318 total bound parameter sets ...  {'domain_name': 'zh.m.n', '_page_title': ' 2008年Google開發者日澳洲站_網路API多層面應用獲重視', '_view_count': 1, '_size': 0, '_date': ' 2024/10/19', '_hour': 14}, {'domain_name': 'zu.m', '_page_title': ' Talk:IFacebook', '_view_count': 1, '_size': 0, '_date': ' 2024/10/19', '_hour': 14})]
(Background on this error at: https://sqlalche.me/e/14/f405)
[2024-10-19T16:56:14.841+0000] {taskinstance.py:1225} INFO - Marking task as FAILED. dag_id=postgres_to_s3, task_id=load_to_s3, run_id=manual__2024-10-19T16:44:14.509632+00:00, execution_date=20241019T164414, start_date=20241019T165614, end_date=20241019T165614
[2024-10-19T16:56:14.897+0000] {taskinstance.py:340} INFO - ::group::Post task execution logs
[2024-10-19T16:56:14.898+0000] {standard_task_runner.py:124} ERROR - Failed to execute job 40 for task load_to_s3 ((psycopg2.errors.UndefinedColumn) column " page_title" of relation "wiki_file" does not exist
LINE 1: INSERT INTO wiki_file (domain_name, " page_title", " view_co...
                                            ^

[SQL: INSERT INTO wiki_file (domain_name, " page_title", " view_count", " size", " date", " hour") VALUES (%(domain_name)s, %(_page_title)s, %(_view_count)s, %(_size)s, %(_date)s, %(_hour)s)]
[parameters: ({'domain_name': 'ace.m', '_page_title': ' Facebook', '_view_count': 2, '_size': 0, '_date': ' 2024/10/19', '_hour': 14}, {'domain_name': 'af.m', '_page_title': ' Google_Chrome', '_view_count': 1, '_size': 0, '_date': ' 2024/10/19', '_hour': 14}, {'domain_name': 'als.m', '_page_title': ' Facebook', '_view_count': 2, '_size': 0, '_date': ' 2024/10/19', '_hour': 14}, {'domain_name': 'ar', '_page_title': ' ملف:2023_Facebook_icon.svg', '_view_count': 1, '_size': 0, '_date': ' 2024/10/19', '_hour': 14}, {'domain_name': 'ar', '_page_title': ' ملف:Facebook_Logo_(2019).png', '_view_count': 1, '_size': 0, '_date': ' 2024/10/19', '_hour': 14}, {'domain_name': 'ar', '_page_title': ' ملف:Facebook_logo_(square).png', '_view_count': 1, '_size': 0, '_date': ' 2024/10/19', '_hour': 14}, {'domain_name': 'ar', '_page_title': ' ملف:Juan_Gris_-_Portrait_of_Pablo_Picasso_-_Google_Art_Project.jpg', '_view_count': 1, '_size': 0, '_date': ' 2024/10/19', '_hour': 14}, {'domain_name': 'ar', '_page_title': ' ملف:Microsoft_Store.svg', '_view_count': 1, '_size': 0, '_date': ' 2024/10/19', '_hour': 14}  ... displaying 10 of 5318 total bound parameter sets ...  {'domain_name': 'zh.m.n', '_page_title': ' 2008年Google開發者日澳洲站_網路API多層面應用獲重視', '_view_count': 1, '_size': 0, '_date': ' 2024/10/19', '_hour': 14}, {'domain_name': 'zu.m', '_page_title': ' Talk:IFacebook', '_view_count': 1, '_size': 0, '_date': ' 2024/10/19', '_hour': 14})]
(Background on this error at: https://sqlalche.me/e/14/f405); 1552)
Traceback (most recent call last):
  File "/home/airflow/.local/lib/python3.12/site-packages/sqlalchemy/engine/base.py", line 1890, in _execute_context
    self.dialect.do_executemany(
  File "/home/airflow/.local/lib/python3.12/site-packages/sqlalchemy/dialects/postgresql/psycopg2.py", line 982, in do_executemany
    context._psycopg2_fetched_rows = xtras.execute_values(
                                     ^^^^^^^^^^^^^^^^^^^^^
  File "/home/airflow/.local/lib/python3.12/site-packages/psycopg2/extras.py", line 1299, in execute_values
    cur.execute(b''.join(parts))
psycopg2.errors.UndefinedColumn: column " page_title" of relation "wiki_file" does not exist
LINE 1: INSERT INTO wiki_file (domain_name, " page_title", " view_co...
                                            ^


The above exception was the direct cause of the following exception:

Traceback (most recent call last):
  File "/home/airflow/.local/lib/python3.12/site-packages/airflow/task/task_runner/standard_task_runner.py", line 117, in _start_by_fork
    ret = args.func(args, dag=self.dag)
          ^^^^^^^^^^^^^^^^^^^^^^^^^^^^^
  File "/home/airflow/.local/lib/python3.12/site-packages/airflow/cli/cli_config.py", line 49, in command
    return func(*args, **kwargs)
           ^^^^^^^^^^^^^^^^^^^^^
  File "/home/airflow/.local/lib/python3.12/site-packages/airflow/utils/cli.py", line 115, in wrapper
    return f(*args, **kwargs)
           ^^^^^^^^^^^^^^^^^^
  File "/home/airflow/.local/lib/python3.12/site-packages/airflow/cli/commands/task_command.py", line 483, in task_run
    task_return_code = _run_task_by_selected_method(args, _dag, ti)
                       ^^^^^^^^^^^^^^^^^^^^^^^^^^^^^^^^^^^^^^^^^^^^
  File "/home/airflow/.local/lib/python3.12/site-packages/airflow/cli/commands/task_command.py", line 256, in _run_task_by_selected_method
    return _run_raw_task(args, ti)
           ^^^^^^^^^^^^^^^^^^^^^^^
  File "/home/airflow/.local/lib/python3.12/site-packages/airflow/cli/commands/task_command.py", line 341, in _run_raw_task
    return ti._run_raw_task(
           ^^^^^^^^^^^^^^^^^
  File "/home/airflow/.local/lib/python3.12/site-packages/airflow/utils/session.py", line 97, in wrapper
    return func(*args, session=session, **kwargs)
           ^^^^^^^^^^^^^^^^^^^^^^^^^^^^^^^^^^^^^^
  File "/home/airflow/.local/lib/python3.12/site-packages/airflow/models/taskinstance.py", line 3004, in _run_raw_task
    return _run_raw_task(
           ^^^^^^^^^^^^^^
  File "/home/airflow/.local/lib/python3.12/site-packages/airflow/models/taskinstance.py", line 273, in _run_raw_task
    TaskInstance._execute_task_with_callbacks(
  File "/home/airflow/.local/lib/python3.12/site-packages/airflow/models/taskinstance.py", line 3158, in _execute_task_with_callbacks
    result = self._execute_task(context, task_orig)
             ^^^^^^^^^^^^^^^^^^^^^^^^^^^^^^^^^^^^^^
  File "/home/airflow/.local/lib/python3.12/site-packages/airflow/models/taskinstance.py", line 3182, in _execute_task
    return _execute_task(self, context, task_orig)
           ^^^^^^^^^^^^^^^^^^^^^^^^^^^^^^^^^^^^^^^
  File "/home/airflow/.local/lib/python3.12/site-packages/airflow/models/taskinstance.py", line 767, in _execute_task
    result = _execute_callable(context=context, **execute_callable_kwargs)
             ^^^^^^^^^^^^^^^^^^^^^^^^^^^^^^^^^^^^^^^^^^^^^^^^^^^^^^^^^^^^^
  File "/home/airflow/.local/lib/python3.12/site-packages/airflow/models/taskinstance.py", line 733, in _execute_callable
    return ExecutionCallableRunner(
           ^^^^^^^^^^^^^^^^^^^^^^^^
  File "/home/airflow/.local/lib/python3.12/site-packages/airflow/utils/operator_helpers.py", line 252, in run
    return self.func(*args, **kwargs)
           ^^^^^^^^^^^^^^^^^^^^^^^^^^
  File "/home/airflow/.local/lib/python3.12/site-packages/airflow/models/baseoperator.py", line 406, in wrapper
    return func(self, *args, **kwargs)
           ^^^^^^^^^^^^^^^^^^^^^^^^^^^
  File "/home/airflow/.local/lib/python3.12/site-packages/airflow/operators/python.py", line 238, in execute
    return_value = self.execute_callable()
                   ^^^^^^^^^^^^^^^^^^^^^^^
  File "/home/airflow/.local/lib/python3.12/site-packages/airflow/operators/python.py", line 256, in execute_callable
    return runner.run(*self.op_args, **self.op_kwargs)
           ^^^^^^^^^^^^^^^^^^^^^^^^^^^^^^^^^^^^^^^^^^^
  File "/home/airflow/.local/lib/python3.12/site-packages/airflow/utils/operator_helpers.py", line 252, in run
    return self.func(*args, **kwargs)
           ^^^^^^^^^^^^^^^^^^^^^^^^^^
  File "/opt/airflow/dags/prod.py", line 48, in load_csv_to_database
    df.to_sql('wiki_file', engine, if_exists='append', index=False)
  File "/home/airflow/.local/lib/python3.12/site-packages/pandas/util/_decorators.py", line 333, in wrapper
    return func(*args, **kwargs)
           ^^^^^^^^^^^^^^^^^^^^^
  File "/home/airflow/.local/lib/python3.12/site-packages/pandas/core/generic.py", line 3008, in to_sql
    return sql.to_sql(
           ^^^^^^^^^^^
  File "/home/airflow/.local/lib/python3.12/site-packages/pandas/io/sql.py", line 788, in to_sql
    return pandas_sql.to_sql(
           ^^^^^^^^^^^^^^^^^^
  File "/home/airflow/.local/lib/python3.12/site-packages/pandas/io/sql.py", line 1958, in to_sql
    total_inserted = sql_engine.insert_records(
                     ^^^^^^^^^^^^^^^^^^^^^^^^^^
  File "/home/airflow/.local/lib/python3.12/site-packages/pandas/io/sql.py", line 1507, in insert_records
    raise err
  File "/home/airflow/.local/lib/python3.12/site-packages/pandas/io/sql.py", line 1498, in insert_records
    return table.insert(chunksize=chunksize, method=method)
           ^^^^^^^^^^^^^^^^^^^^^^^^^^^^^^^^^^^^^^^^^^^^^^^^
  File "/home/airflow/.local/lib/python3.12/site-packages/pandas/io/sql.py", line 1059, in insert
    num_inserted = exec_insert(conn, keys, chunk_iter)
                   ^^^^^^^^^^^^^^^^^^^^^^^^^^^^^^^^^^^
  File "/home/airflow/.local/lib/python3.12/site-packages/pandas/io/sql.py", line 951, in _execute_insert
    result = conn.execute(self.table.insert(), data)
             ^^^^^^^^^^^^^^^^^^^^^^^^^^^^^^^^^^^^^^^
  File "/home/airflow/.local/lib/python3.12/site-packages/sqlalchemy/engine/base.py", line 1385, in execute
    return meth(self, multiparams, params, _EMPTY_EXECUTION_OPTS)
           ^^^^^^^^^^^^^^^^^^^^^^^^^^^^^^^^^^^^^^^^^^^^^^^^^^^^^^
  File "/home/airflow/.local/lib/python3.12/site-packages/sqlalchemy/sql/elements.py", line 334, in _execute_on_connection
    return connection._execute_clauseelement(
           ^^^^^^^^^^^^^^^^^^^^^^^^^^^^^^^^^^
  File "/home/airflow/.local/lib/python3.12/site-packages/sqlalchemy/engine/base.py", line 1577, in _execute_clauseelement
    ret = self._execute_context(
          ^^^^^^^^^^^^^^^^^^^^^^
  File "/home/airflow/.local/lib/python3.12/site-packages/sqlalchemy/engine/base.py", line 1953, in _execute_context
    self._handle_dbapi_exception(
  File "/home/airflow/.local/lib/python3.12/site-packages/sqlalchemy/engine/base.py", line 2134, in _handle_dbapi_exception
    util.raise_(
  File "/home/airflow/.local/lib/python3.12/site-packages/sqlalchemy/util/compat.py", line 211, in raise_
    raise exception
  File "/home/airflow/.local/lib/python3.12/site-packages/sqlalchemy/engine/base.py", line 1890, in _execute_context
    self.dialect.do_executemany(
  File "/home/airflow/.local/lib/python3.12/site-packages/sqlalchemy/dialects/postgresql/psycopg2.py", line 982, in do_executemany
    context._psycopg2_fetched_rows = xtras.execute_values(
                                     ^^^^^^^^^^^^^^^^^^^^^
  File "/home/airflow/.local/lib/python3.12/site-packages/psycopg2/extras.py", line 1299, in execute_values
    cur.execute(b''.join(parts))
sqlalchemy.exc.ProgrammingError: (psycopg2.errors.UndefinedColumn) column " page_title" of relation "wiki_file" does not exist
LINE 1: INSERT INTO wiki_file (domain_name, " page_title", " view_co...
                                            ^

[SQL: INSERT INTO wiki_file (domain_name, " page_title", " view_count", " size", " date", " hour") VALUES (%(domain_name)s, %(_page_title)s, %(_view_count)s, %(_size)s, %(_date)s, %(_hour)s)]
[parameters: ({'domain_name': 'ace.m', '_page_title': ' Facebook', '_view_count': 2, '_size': 0, '_date': ' 2024/10/19', '_hour': 14}, {'domain_name': 'af.m', '_page_title': ' Google_Chrome', '_view_count': 1, '_size': 0, '_date': ' 2024/10/19', '_hour': 14}, {'domain_name': 'als.m', '_page_title': ' Facebook', '_view_count': 2, '_size': 0, '_date': ' 2024/10/19', '_hour': 14}, {'domain_name': 'ar', '_page_title': ' ملف:2023_Facebook_icon.svg', '_view_count': 1, '_size': 0, '_date': ' 2024/10/19', '_hour': 14}, {'domain_name': 'ar', '_page_title': ' ملف:Facebook_Logo_(2019).png', '_view_count': 1, '_size': 0, '_date': ' 2024/10/19', '_hour': 14}, {'domain_name': 'ar', '_page_title': ' ملف:Facebook_logo_(square).png', '_view_count': 1, '_size': 0, '_date': ' 2024/10/19', '_hour': 14}, {'domain_name': 'ar', '_page_title': ' ملف:Juan_Gris_-_Portrait_of_Pablo_Picasso_-_Google_Art_Project.jpg', '_view_count': 1, '_size': 0, '_date': ' 2024/10/19', '_hour': 14}, {'domain_name': 'ar', '_page_title': ' ملف:Microsoft_Store.svg', '_view_count': 1, '_size': 0, '_date': ' 2024/10/19', '_hour': 14}  ... displaying 10 of 5318 total bound parameter sets ...  {'domain_name': 'zh.m.n', '_page_title': ' 2008年Google開發者日澳洲站_網路API多層面應用獲重視', '_view_count': 1, '_size': 0, '_date': ' 2024/10/19', '_hour': 14}, {'domain_name': 'zu.m', '_page_title': ' Talk:IFacebook', '_view_count': 1, '_size': 0, '_date': ' 2024/10/19', '_hour': 14})]
(Background on this error at: https://sqlalche.me/e/14/f405)
[2024-10-19T16:56:14.958+0000] {local_task_job_runner.py:266} INFO - Task exited with return code 1
[2024-10-19T16:56:14.990+0000] {taskinstance.py:3900} INFO - 0 downstream tasks scheduled from follow-on schedule check
[2024-10-19T16:56:14.999+0000] {local_task_job_runner.py:245} INFO - ::endgroup::
