[2024-10-19T15:21:47.735+0000] {local_task_job_runner.py:123} INFO - ::group::Pre task execution logs
[2024-10-19T15:21:47.771+0000] {taskinstance.py:2612} INFO - Dependencies all met for dep_context=non-requeueable deps ti=<TaskInstance: postgres_to_s3.bash_task1 manual__2024-10-19T15:21:45.681062+00:00 [queued]>
[2024-10-19T15:21:47.793+0000] {taskinstance.py:2612} INFO - Dependencies all met for dep_context=requeueable deps ti=<TaskInstance: postgres_to_s3.bash_task1 manual__2024-10-19T15:21:45.681062+00:00 [queued]>
[2024-10-19T15:21:47.794+0000] {taskinstance.py:2865} INFO - Starting attempt 1 of 1
[2024-10-19T15:21:47.827+0000] {taskinstance.py:2888} INFO - Executing <Task(BashOperator): bash_task1> on 2024-10-19 15:21:45.681062+00:00
[2024-10-19T15:21:47.840+0000] {warnings.py:112} WARNING - /home/***/.local/lib/python3.12/site-packages/***/task/task_runner/standard_task_runner.py:70: DeprecationWarning: This process (pid=147) is multi-threaded, use of fork() may lead to deadlocks in the child.
  pid = os.fork()

[2024-10-19T15:21:47.844+0000] {standard_task_runner.py:72} INFO - Started process 156 to run task
[2024-10-19T15:21:47.851+0000] {standard_task_runner.py:104} INFO - Running: ['***', 'tasks', 'run', 'postgres_to_s3', 'bash_task1', 'manual__2024-10-19T15:21:45.681062+00:00', '--job-id', '7', '--raw', '--subdir', 'DAGS_FOLDER/prod.py', '--cfg-path', '/tmp/tmposw9_9lw']
[2024-10-19T15:21:47.856+0000] {standard_task_runner.py:105} INFO - Job 7: Subtask bash_task1
[2024-10-19T15:21:47.981+0000] {task_command.py:467} INFO - Running <TaskInstance: postgres_to_s3.bash_task1 manual__2024-10-19T15:21:45.681062+00:00 [running]> on host 533638d20908
[2024-10-19T15:21:48.569+0000] {taskinstance.py:3131} INFO - Exporting env vars: AIRFLOW_CTX_DAG_OWNER='protectorate' AIRFLOW_CTX_DAG_ID='postgres_to_s3' AIRFLOW_CTX_TASK_ID='bash_task1' AIRFLOW_CTX_EXECUTION_DATE='2024-10-19T15:21:45.681062+00:00' AIRFLOW_CTX_TRY_NUMBER='1' AIRFLOW_CTX_DAG_RUN_ID='manual__2024-10-19T15:21:45.681062+00:00'
[2024-10-19T15:21:48.571+0000] {taskinstance.py:731} INFO - ::endgroup::
[2024-10-19T15:21:48.601+0000] {subprocess.py:63} INFO - Tmp dir root location: /tmp
[2024-10-19T15:21:48.604+0000] {subprocess.py:75} INFO - Running command: ['/usr/bin/bash', '-c', './opt/***/dags/wiki_log_file.sh ']
[2024-10-19T15:21:48.623+0000] {subprocess.py:86} INFO - Output:
[2024-10-19T15:21:48.664+0000] {subprocess.py:93} INFO - /usr/bin/bash: line 1: ./opt/***/dags/wiki_log_file.sh: No such file or directory
[2024-10-19T15:21:48.671+0000] {subprocess.py:97} INFO - Command exited with return code 127
[2024-10-19T15:21:48.716+0000] {taskinstance.py:3310} ERROR - Task failed with exception
Traceback (most recent call last):
  File "/home/airflow/.local/lib/python3.12/site-packages/airflow/models/taskinstance.py", line 767, in _execute_task
    result = _execute_callable(context=context, **execute_callable_kwargs)
             ^^^^^^^^^^^^^^^^^^^^^^^^^^^^^^^^^^^^^^^^^^^^^^^^^^^^^^^^^^^^^
  File "/home/airflow/.local/lib/python3.12/site-packages/airflow/models/taskinstance.py", line 733, in _execute_callable
    return ExecutionCallableRunner(
           ^^^^^^^^^^^^^^^^^^^^^^^^
  File "/home/airflow/.local/lib/python3.12/site-packages/airflow/utils/operator_helpers.py", line 252, in run
    return self.func(*args, **kwargs)
           ^^^^^^^^^^^^^^^^^^^^^^^^^^
  File "/home/airflow/.local/lib/python3.12/site-packages/airflow/models/baseoperator.py", line 406, in wrapper
    return func(self, *args, **kwargs)
           ^^^^^^^^^^^^^^^^^^^^^^^^^^^
  File "/home/airflow/.local/lib/python3.12/site-packages/airflow/operators/bash.py", line 249, in execute
    raise AirflowException(
airflow.exceptions.AirflowException: Bash command failed. The command returned a non-zero exit code 127.
[2024-10-19T15:21:48.727+0000] {taskinstance.py:1225} INFO - Marking task as FAILED. dag_id=postgres_to_s3, task_id=bash_task1, run_id=manual__2024-10-19T15:21:45.681062+00:00, execution_date=20241019T152145, start_date=20241019T152147, end_date=20241019T152148
[2024-10-19T15:21:48.777+0000] {taskinstance.py:340} INFO - ::group::Post task execution logs
[2024-10-19T15:21:48.779+0000] {standard_task_runner.py:124} ERROR - Failed to execute job 7 for task bash_task1 (Bash command failed. The command returned a non-zero exit code 127.; 156)
Traceback (most recent call last):
  File "/home/airflow/.local/lib/python3.12/site-packages/airflow/task/task_runner/standard_task_runner.py", line 117, in _start_by_fork
    ret = args.func(args, dag=self.dag)
          ^^^^^^^^^^^^^^^^^^^^^^^^^^^^^
  File "/home/airflow/.local/lib/python3.12/site-packages/airflow/cli/cli_config.py", line 49, in command
    return func(*args, **kwargs)
           ^^^^^^^^^^^^^^^^^^^^^
  File "/home/airflow/.local/lib/python3.12/site-packages/airflow/utils/cli.py", line 115, in wrapper
    return f(*args, **kwargs)
           ^^^^^^^^^^^^^^^^^^
  File "/home/airflow/.local/lib/python3.12/site-packages/airflow/cli/commands/task_command.py", line 483, in task_run
    task_return_code = _run_task_by_selected_method(args, _dag, ti)
                       ^^^^^^^^^^^^^^^^^^^^^^^^^^^^^^^^^^^^^^^^^^^^
  File "/home/airflow/.local/lib/python3.12/site-packages/airflow/cli/commands/task_command.py", line 256, in _run_task_by_selected_method
    return _run_raw_task(args, ti)
           ^^^^^^^^^^^^^^^^^^^^^^^
  File "/home/airflow/.local/lib/python3.12/site-packages/airflow/cli/commands/task_command.py", line 341, in _run_raw_task
    return ti._run_raw_task(
           ^^^^^^^^^^^^^^^^^
  File "/home/airflow/.local/lib/python3.12/site-packages/airflow/utils/session.py", line 97, in wrapper
    return func(*args, session=session, **kwargs)
           ^^^^^^^^^^^^^^^^^^^^^^^^^^^^^^^^^^^^^^
  File "/home/airflow/.local/lib/python3.12/site-packages/airflow/models/taskinstance.py", line 3004, in _run_raw_task
    return _run_raw_task(
           ^^^^^^^^^^^^^^
  File "/home/airflow/.local/lib/python3.12/site-packages/airflow/models/taskinstance.py", line 273, in _run_raw_task
    TaskInstance._execute_task_with_callbacks(
  File "/home/airflow/.local/lib/python3.12/site-packages/airflow/models/taskinstance.py", line 3158, in _execute_task_with_callbacks
    result = self._execute_task(context, task_orig)
             ^^^^^^^^^^^^^^^^^^^^^^^^^^^^^^^^^^^^^^
  File "/home/airflow/.local/lib/python3.12/site-packages/airflow/models/taskinstance.py", line 3182, in _execute_task
    return _execute_task(self, context, task_orig)
           ^^^^^^^^^^^^^^^^^^^^^^^^^^^^^^^^^^^^^^^
  File "/home/airflow/.local/lib/python3.12/site-packages/airflow/models/taskinstance.py", line 767, in _execute_task
    result = _execute_callable(context=context, **execute_callable_kwargs)
             ^^^^^^^^^^^^^^^^^^^^^^^^^^^^^^^^^^^^^^^^^^^^^^^^^^^^^^^^^^^^^
  File "/home/airflow/.local/lib/python3.12/site-packages/airflow/models/taskinstance.py", line 733, in _execute_callable
    return ExecutionCallableRunner(
           ^^^^^^^^^^^^^^^^^^^^^^^^
  File "/home/airflow/.local/lib/python3.12/site-packages/airflow/utils/operator_helpers.py", line 252, in run
    return self.func(*args, **kwargs)
           ^^^^^^^^^^^^^^^^^^^^^^^^^^
  File "/home/airflow/.local/lib/python3.12/site-packages/airflow/models/baseoperator.py", line 406, in wrapper
    return func(self, *args, **kwargs)
           ^^^^^^^^^^^^^^^^^^^^^^^^^^^
  File "/home/airflow/.local/lib/python3.12/site-packages/airflow/operators/bash.py", line 249, in execute
    raise AirflowException(
airflow.exceptions.AirflowException: Bash command failed. The command returned a non-zero exit code 127.
[2024-10-19T15:21:48.857+0000] {local_task_job_runner.py:266} INFO - Task exited with return code 1
[2024-10-19T15:21:48.883+0000] {local_task_job_runner.py:245} INFO - ::endgroup::
