[2024-11-25T01:58:16.131+0000] {local_task_job_runner.py:123} INFO - ::group::Pre task execution logs
[2024-11-25T01:58:16.273+0000] {taskinstance.py:2612} INFO - Dependencies all met for dep_context=non-requeueable deps ti=<TaskInstance: create_country_table.create_postgres_table manual__2024-11-25T01:50:49.626301+00:00 [queued]>
[2024-11-25T01:58:16.388+0000] {taskinstance.py:2612} INFO - Dependencies all met for dep_context=requeueable deps ti=<TaskInstance: create_country_table.create_postgres_table manual__2024-11-25T01:50:49.626301+00:00 [queued]>
[2024-11-25T01:58:16.397+0000] {taskinstance.py:2865} INFO - Starting attempt 4 of 5
[2024-11-25T01:58:16.550+0000] {taskinstance.py:2888} INFO - Executing <Task(PostgresOperator): create_postgres_table> on 2024-11-25 01:50:49.626301+00:00
[2024-11-25T01:58:16.573+0000] {warnings.py:112} WARNING - /home/***/.local/lib/python3.12/site-packages/***/task/task_runner/standard_task_runner.py:70: DeprecationWarning: This process (pid=356) is multi-threaded, use of fork() may lead to deadlocks in the child.
  pid = os.fork()

[2024-11-25T01:58:16.586+0000] {standard_task_runner.py:104} INFO - Running: ['***', 'tasks', 'run', 'create_country_table', 'create_postgres_table', 'manual__2024-11-25T01:50:49.626301+00:00', '--job-id', '123', '--raw', '--subdir', 'DAGS_FOLDER/capstone_***/create_table.py', '--cfg-path', '/tmp/tmpm8p0e2bh']
[2024-11-25T01:58:16.590+0000] {standard_task_runner.py:72} INFO - Started process 363 to run task
[2024-11-25T01:58:16.592+0000] {standard_task_runner.py:105} INFO - Job 123: Subtask create_postgres_table
[2024-11-25T01:58:16.876+0000] {task_command.py:467} INFO - Running <TaskInstance: create_country_table.create_postgres_table manual__2024-11-25T01:50:49.626301+00:00 [running]> on host 18d777ba90d1
[2024-11-25T01:58:17.436+0000] {taskinstance.py:3131} INFO - Exporting env vars: AIRFLOW_CTX_DAG_OWNER='adewunmi' AIRFLOW_CTX_DAG_ID='create_country_table' AIRFLOW_CTX_TASK_ID='create_postgres_table' AIRFLOW_CTX_EXECUTION_DATE='2024-11-25T01:50:49.626301+00:00' AIRFLOW_CTX_TRY_NUMBER='4' AIRFLOW_CTX_DAG_RUN_ID='manual__2024-11-25T01:50:49.626301+00:00'
[2024-11-25T01:58:17.439+0000] {taskinstance.py:731} INFO - ::endgroup::
[2024-11-25T01:58:17.517+0000] {sql.py:266} INFO - Executing: 
        CREATE TABLE country_data (
            country_name VARCHAR(255) not null,
            independence BOOLEAN,
            united_nation_members BOOLEAN,
            start_of_week VARCHAR(50),
            official_country_name VARCHAR(255),
            common_native_name VARCHAR(255),
            currency_code TEXT,
            currency_name TEXT,
            currency_symbol TEXT,
            country_code TEXT,
            capital VARCHAR(100),
            region VARCHAR(100),
            subregion VARCHAR(100),
            languages TEXT,
            area FLOAT,
            population BIGINT,
            continents VARCHAR(100),
            PRIMARY KEY (country_name)
        );
        
[2024-11-25T01:58:17.561+0000] {base.py:84} INFO - Retrieving connection 'postgres_id'
[2024-11-25T01:58:17.600+0000] {base.py:84} INFO - Retrieving connection 'postgres_id'
[2024-11-25T01:58:17.616+0000] {sql.py:509} INFO - Running statement: 
        CREATE TABLE country_data (
            country_name VARCHAR(255) not null,
            independence BOOLEAN,
            united_nation_members BOOLEAN,
            start_of_week VARCHAR(50),
            official_country_name VARCHAR(255),
            common_native_name VARCHAR(255),
            currency_code TEXT,
            currency_name TEXT,
            currency_symbol TEXT,
            country_code TEXT,
            capital VARCHAR(100),
            region VARCHAR(100),
            subregion VARCHAR(100),
            languages TEXT,
            area FLOAT,
            population BIGINT,
            continents VARCHAR(100),
            PRIMARY KEY (country_name)
        );
        , parameters: None
[2024-11-25T01:58:17.629+0000] {taskinstance.py:3310} ERROR - Task failed with exception
Traceback (most recent call last):
  File "/home/airflow/.local/lib/python3.12/site-packages/airflow/models/taskinstance.py", line 767, in _execute_task
    result = _execute_callable(context=context, **execute_callable_kwargs)
             ^^^^^^^^^^^^^^^^^^^^^^^^^^^^^^^^^^^^^^^^^^^^^^^^^^^^^^^^^^^^^
  File "/home/airflow/.local/lib/python3.12/site-packages/airflow/models/taskinstance.py", line 733, in _execute_callable
    return ExecutionCallableRunner(
           ^^^^^^^^^^^^^^^^^^^^^^^^
  File "/home/airflow/.local/lib/python3.12/site-packages/airflow/utils/operator_helpers.py", line 252, in run
    return self.func(*args, **kwargs)
           ^^^^^^^^^^^^^^^^^^^^^^^^^^
  File "/home/airflow/.local/lib/python3.12/site-packages/airflow/models/baseoperator.py", line 406, in wrapper
    return func(self, *args, **kwargs)
           ^^^^^^^^^^^^^^^^^^^^^^^^^^^
  File "/home/airflow/.local/lib/python3.12/site-packages/airflow/providers/common/sql/operators/sql.py", line 272, in execute
    output = hook.run(
             ^^^^^^^^^
  File "/home/airflow/.local/lib/python3.12/site-packages/airflow/providers/common/sql/hooks/sql.py", line 456, in run
    self._run_command(cur, sql_statement, parameters)
  File "/home/airflow/.local/lib/python3.12/site-packages/airflow/providers/common/sql/hooks/sql.py", line 514, in _run_command
    cur.execute(sql_statement)
psycopg2.errors.DuplicateTable: relation "country_data" already exists

[2024-11-25T01:58:17.720+0000] {taskinstance.py:1225} INFO - Marking task as UP_FOR_RETRY. dag_id=create_country_table, task_id=create_postgres_table, run_id=manual__2024-11-25T01:50:49.626301+00:00, execution_date=20241125T015049, start_date=20241125T015816, end_date=20241125T015817
[2024-11-25T01:58:17.914+0000] {taskinstance.py:340} INFO - ::group::Post task execution logs
[2024-11-25T01:58:17.933+0000] {standard_task_runner.py:124} ERROR - Failed to execute job 123 for task create_postgres_table (relation "country_data" already exists
; 363)
Traceback (most recent call last):
  File "/home/airflow/.local/lib/python3.12/site-packages/airflow/task/task_runner/standard_task_runner.py", line 117, in _start_by_fork
    ret = args.func(args, dag=self.dag)
          ^^^^^^^^^^^^^^^^^^^^^^^^^^^^^
  File "/home/airflow/.local/lib/python3.12/site-packages/airflow/cli/cli_config.py", line 49, in command
    return func(*args, **kwargs)
           ^^^^^^^^^^^^^^^^^^^^^
  File "/home/airflow/.local/lib/python3.12/site-packages/airflow/utils/cli.py", line 115, in wrapper
    return f(*args, **kwargs)
           ^^^^^^^^^^^^^^^^^^
  File "/home/airflow/.local/lib/python3.12/site-packages/airflow/cli/commands/task_command.py", line 483, in task_run
    task_return_code = _run_task_by_selected_method(args, _dag, ti)
                       ^^^^^^^^^^^^^^^^^^^^^^^^^^^^^^^^^^^^^^^^^^^^
  File "/home/airflow/.local/lib/python3.12/site-packages/airflow/cli/commands/task_command.py", line 256, in _run_task_by_selected_method
    return _run_raw_task(args, ti)
           ^^^^^^^^^^^^^^^^^^^^^^^
  File "/home/airflow/.local/lib/python3.12/site-packages/airflow/cli/commands/task_command.py", line 341, in _run_raw_task
    return ti._run_raw_task(
           ^^^^^^^^^^^^^^^^^
  File "/home/airflow/.local/lib/python3.12/site-packages/airflow/utils/session.py", line 97, in wrapper
    return func(*args, session=session, **kwargs)
           ^^^^^^^^^^^^^^^^^^^^^^^^^^^^^^^^^^^^^^
  File "/home/airflow/.local/lib/python3.12/site-packages/airflow/models/taskinstance.py", line 3004, in _run_raw_task
    return _run_raw_task(
           ^^^^^^^^^^^^^^
  File "/home/airflow/.local/lib/python3.12/site-packages/airflow/models/taskinstance.py", line 273, in _run_raw_task
    TaskInstance._execute_task_with_callbacks(
  File "/home/airflow/.local/lib/python3.12/site-packages/airflow/models/taskinstance.py", line 3158, in _execute_task_with_callbacks
    result = self._execute_task(context, task_orig)
             ^^^^^^^^^^^^^^^^^^^^^^^^^^^^^^^^^^^^^^
  File "/home/airflow/.local/lib/python3.12/site-packages/airflow/models/taskinstance.py", line 3182, in _execute_task
    return _execute_task(self, context, task_orig)
           ^^^^^^^^^^^^^^^^^^^^^^^^^^^^^^^^^^^^^^^
  File "/home/airflow/.local/lib/python3.12/site-packages/airflow/models/taskinstance.py", line 767, in _execute_task
    result = _execute_callable(context=context, **execute_callable_kwargs)
             ^^^^^^^^^^^^^^^^^^^^^^^^^^^^^^^^^^^^^^^^^^^^^^^^^^^^^^^^^^^^^
  File "/home/airflow/.local/lib/python3.12/site-packages/airflow/models/taskinstance.py", line 733, in _execute_callable
    return ExecutionCallableRunner(
           ^^^^^^^^^^^^^^^^^^^^^^^^
  File "/home/airflow/.local/lib/python3.12/site-packages/airflow/utils/operator_helpers.py", line 252, in run
    return self.func(*args, **kwargs)
           ^^^^^^^^^^^^^^^^^^^^^^^^^^
  File "/home/airflow/.local/lib/python3.12/site-packages/airflow/models/baseoperator.py", line 406, in wrapper
    return func(self, *args, **kwargs)
           ^^^^^^^^^^^^^^^^^^^^^^^^^^^
  File "/home/airflow/.local/lib/python3.12/site-packages/airflow/providers/common/sql/operators/sql.py", line 272, in execute
    output = hook.run(
             ^^^^^^^^^
  File "/home/airflow/.local/lib/python3.12/site-packages/airflow/providers/common/sql/hooks/sql.py", line 456, in run
    self._run_command(cur, sql_statement, parameters)
  File "/home/airflow/.local/lib/python3.12/site-packages/airflow/providers/common/sql/hooks/sql.py", line 514, in _run_command
    cur.execute(sql_statement)
psycopg2.errors.DuplicateTable: relation "country_data" already exists

[2024-11-25T01:58:18.129+0000] {local_task_job_runner.py:266} INFO - Task exited with return code 1
[2024-11-25T01:58:18.296+0000] {taskinstance.py:3900} INFO - 0 downstream tasks scheduled from follow-on schedule check
[2024-11-25T01:58:18.344+0000] {local_task_job_runner.py:245} INFO - ::endgroup::
